Workbook
Name Source: 'เช็คราคา'!$A$80:$D$87
Name Salad: 'เช็คราคา'!$A$216:$C$226
Name Noodle: 'เช็คราคา'!$A$122:$C$134
Name Beacon: 'เช็คราคา'!$A$88:$D$92
Name ball: 'เช็คราคา'!$A$146:$D$176
Name Pices: 'เช็คราคา'!$A$43:$D$59
Name Fried: 'เช็คราคา'!$A$62:$D$73
Name meat: 'เช็คราคา'!$A$135:$C$145
Name Fresh: 'เช็คราคา'!$A$98:$C$121
Name Nammmm: 'เช็คราคา'!$A$31:$C$41
Name Grill: 'เช็คราคา'!$A$202:$D$215
Name Fish: 'เช็คราคา'!$A$177:$D$188
Name Pork1: 'เช็คราคา'!$A$1:$C$30
Name bar: 'เช็คราคา'!$A$189:$D$199
Name InPork: 'เช็คราคา'!$A$74:$D$79

Sheet export_items
A1: =IFERROR(__xludf.DUMMYFUNCTION("QUERY(IMPORTRANGE(""https://docs.google.com/spreadsheets/d/1LgvW4Yly4zdVOUCZgROMSAP5uJtTP22RoI-4tTi5cwY/edit"", ""export_items!A:Z""), ""SELECT * WHERE Col1 IS NOT NULL"", 1)"),"Handle") -> Handle | B1: =IFERROR(__xludf.DUMMYFUNCTION("""COMPUTED_VALUE"""),"SKU") -> SKU | C1: =IFERROR(__xludf.DUMMYFUNCTION("""COMPUTED_VALUE"""),"Name") -> Name | D1: =IFERROR(__xludf.DUMMYFUNCTION("""COMPUTED_VALUE"""),"Category") -> Category | E1: =IFERROR(__xludf.DUMMYFUNCTION("""COMPUTED_VALUE"""),"Description") -> Description | F1: =IFERROR(__xludf.DUMMYFUNCTION("""COMPUTED_VALUE"""),"Sold by weight") -> Sold by weight | G1: =IFERROR(__xludf.DUMMYFUNCTION("""COMPUTED_VALUE"""),"Option 1 name") -> Option 1 name | H1: =IFERROR(__xludf.DUMMYFUNCTION("""COMPUTED_VALUE"""),"Option 1 value") -> Option 1 value | I1: =IFERROR(__xludf.DUMMYFUNCTION("""COMPUTED_VALUE"""),"Option 2 name") -> Option 2 name | J1: =IFERROR(__xludf.DUMMYFUNCTION("""COMPUTED_VALUE"""),"Option 2 value") -> Option 2 value | K1: =IFERROR(__xludf.DUMMYFUNCTION("""COMPUTED_VALUE"""),"Option 3 name") -> Option 3 name | L1: =IFERROR(__xludf.DUMMYFUNCTION("""COMPUTED_VALUE"""),"Option 3 value") -> Option 3 value | M1: =IFERROR(__xludf.DUMMYFUNCTION("""COMPUTED_VALUE"""),"Cost") -> Cost | N1: =IFERROR(__xludf.DUMMYFUNCTION("""COMPUTED_VALUE"""),"Barcode") -> Barcode | O1: =IFERROR(__xludf.DUMMYFUNCTION("""COMPUTED_VALUE"""),"SKU of included item") -> SKU of included item | P1: =IFERROR(__xludf.DUMMYFUNCTION("""COMPUTED_VALUE"""),"Quantity of included item") -> Quantity of included item | Q1: =IFERROR(__xludf.DUMMYFUNCTION("""COMPUTED_VALUE"""),"Track stock") -> Track stock | R1: =IFERROR(__xludf.DUMMYFUNCTION("""COMPUTED_VALUE"""),"Use production") -> Use production | S1: =IFERROR(__xludf.DUMMYFUNCTION("""COMPUTED_VALUE"""),"Supplier") -> Supplier | T1: =IFERROR(__xludf.DUMMYFUNCTION("""COMPUTED_VALUE"""),"Purchase cost") -> Purchase cost | U1: =IFERROR(__xludf.DUMMYFUNCTION("""COMPUTED_VALUE"""),"Available for sale [ห้องเย็นทองสุข สาขาโพนทอง]") -> Available for sale [ห้องเย็นทองสุข สาขาโพนทอง] | V1: =IFERROR(__xludf.DUMMYFUNCTION("""COMPUTED_VALUE"""),"Price [ห้องเย็นทองสุข สาขาโพนทอง]") -> Price [ห้องเย็นทองสุข สาขาโพนทอง] | W1: =IFERROR(__xludf.DUMMYFUNCTION("""COMPUTED_VALUE"""),"In stock [ห้องเย็นทองสุข สาขาโพนทอง]") -> In stock [ห้องเย็นทองสุข สาขาโพนทอง] | X1: =IFERROR(__xludf.DUMMYFUNCTION("""COMPUTED_VALUE"""),"Low stock [ห้องเย็นทองสุข สาขาโพนทอง]") -> Low stock [ห้องเย็นทองสุข สาขาโพนทอง] | Y1: =IFERROR(__xludf.DUMMYFUNCTION("""COMPUTED_VALUE"""),"Optimal stock [ห้องเย็นทองสุข สาขาโพนทอง]") -> Optimal stock [ห้องเย็นทองสุข สาขาโพนทอง] | Z1: =IFERROR(__xludf.DUMMYFUNCTION("""COMPUTED_VALUE"""),"")
A2: =IFERROR(__xludf.DUMMYFUNCTION("""COMPUTED_VALUE"""),"ผัก-1") -> ผัก-1 | B2: =IFERROR(__xludf.DUMMYFUNCTION("""COMPUTED_VALUE"""),90001.0) -> 90001 | C2: =IFERROR(__xludf.DUMMYFUNCTION("""COMPUTED_VALUE"""),"(A) ผัก") -> (A) ผัก | E2: =IFERROR(__xludf.DUMMYFUNCTION("""COMPUTED_VALUE"""),"<p>X</p>") -> <p>X</p> | F2: =IFERROR(__xludf.DUMMYFUNCTION("""COMPUTED_VALUE"""),"Y") -> Y | M2: =IFERROR(__xludf.DUMMYFUNCTION("""COMPUTED_VALUE"""),0.8) -> 0.8 | N2: =IFERROR(__xludf.DUMMYFUNCTION("""COMPUTED_VALUE"""),90001.0) -> 90001 | Q2: =IFERROR(__xludf.DUMMYFUNCTION("""COMPUTED_VALUE"""),"N") -> N | U2: =IFERROR(__xludf.DUMMYFUNCTION("""COMPUTED_VALUE"""),"Y") -> Y | V2: =IFERROR(__xludf.DUMMYFUNCTION("""COMPUTED_VALUE"""),1.0) -> 1
A3: =IFERROR(__xludf.DUMMYFUNCTION("""COMPUTED_VALUE"""),"(b)-เบิก-กระดาษม้วน") -> (b)-เบิก-กระดาษม้วน | B3: =IFERROR(__xludf.DUMMYFUNCTION("""COMPUTED_VALUE"""),10703.0) -> 10703 | C3: =IFERROR(__xludf.DUMMYFUNCTION("""COMPUTED_VALUE"""),"(B) เบิก กระดาษม้วน") -> (B) เบิก กระดาษม้วน | F3: =IFERROR(__xludf.DUMMYFUNCTION("""COMPUTED_VALUE"""),"N") -> N | M3: =IFERROR(__xludf.DUMMYFUNCTION("""COMPUTED_VALUE"""),19.33) -> 19.33 | Q3: =IFERROR(__xludf.DUMMYFUNCTION("""COMPUTED_VALUE"""),"Y") -> Y | U3: =IFERROR(__xludf.DUMMYFUNCTION("""COMPUTED_VALUE"""),"Y") -> Y | V3: =IFERROR(__xludf.DUMMYFUNCTION("""COMPUTED_VALUE"""),30.0) -> 30 | W3: =IFERROR(__xludf.DUMMYFUNCTION("""COMPUTED_VALUE"""),62.0) -> 62
A4: =IFERROR(__xludf.DUMMYFUNCTION("""COMPUTED_VALUE"""),"(a)-เบิกหมูกระทะ-น้ำ(ถัง)") -> (a)-เบิกหมูกระทะ-น้ำ(ถัง) | B4: =IFERROR(__xludf.DUMMYFUNCTION("""COMPUTED_VALUE"""),10616.0) -> 10616 | C4: =IFERROR(__xludf.DUMMYFUNCTION("""COMPUTED_VALUE"""),"(B) เบิกหมูกระทะ น้ำ(ถัง)") -> (B) เบิกหมูกระทะ น้ำ(ถัง) | F4: =IFERROR(__xludf.DUMMYFUNCTION("""COMPUTED_VALUE"""),"N") -> N | M4: =IFERROR(__xludf.DUMMYFUNCTION("""COMPUTED_VALUE"""),13.0) -> 13 | Q4: =IFERROR(__xludf.DUMMYFUNCTION("""COMPUTED_VALUE"""),"N") -> N | U4: =IFERROR(__xludf.DUMMYFUNCTION("""COMPUTED_VALUE"""),"Y") -> Y | V4: =IFERROR(__xludf.DUMMYFUNCTION("""COMPUTED_VALUE"""),13.0) -> 13
A5: =IFERROR(__xludf.DUMMYFUNCTION("""COMPUTED_VALUE"""),"dd-สามชั้นกระทะ-2-แถว-1kg") -> dd-สามชั้นกระทะ-2-แถว-1kg | B5: =IFERROR(__xludf.DUMMYFUNCTION("""COMPUTED_VALUE"""),10821.0) -> 10821 | C5: =IFERROR(__xludf.DUMMYFUNCTION("""COMPUTED_VALUE"""),"(S) DD สามชั้นสไลด์ชาบู 1Kg") -> (S) DD สามชั้นสไลด์ชาบู 1Kg | D5: =IFERROR(__xludf.DUMMYFUNCTION("""COMPUTED_VALUE"""),"**ลัง มหาชัย") -> **ลัง มหาชัย | E5: =IFERROR(__xludf.DUMMYFUNCTION("""COMPUTED_VALUE"""),"<p>1</p>") -> <p>1</p> | F5: =IFERROR(__xludf.DUMMYFUNCTION("""COMPUTED_VALUE"""),"N") -> N | M5: =IFERROR(__xludf.DUMMYFUNCTION("""COMPUTED_VALUE"""),138.85) -> 138.85 | N5: =IFERROR(__xludf.DUMMYFUNCTION("""COMPUTED_VALUE"""),10821.0) -> 10821 | Q5: =IFERROR(__xludf.DUMMYFUNCTION("""COMPUTED_VALUE"""),"Y") -> Y | S5: =IFERROR(__xludf.DUMMYFUNCTION("""COMPUTED_VALUE"""),"ขึ้นของมหาชัย") -> ขึ้นของมหาชัย | T5: =IFERROR(__xludf.DUMMYFUNCTION("""COMPUTED_VALUE"""),134.0) -> 134 | U5: =IFERROR(__xludf.DUMMYFUNCTION("""COMPUTED_VALUE"""),"Y") -> Y | V5: =IFERROR(__xludf.DUMMYFUNCTION("""COMPUTED_VALUE"""),170.0) -> 170 | W5: =IFERROR(__xludf.DUMMYFUNCTION("""COMPUTED_VALUE"""),66.0) -> 66 | X5: =IFERROR(__xludf.DUMMYFUNCTION("""COMPUTED_VALUE"""),10.0) -> 10 | Y5: =IFERROR(__xludf.DUMMYFUNCTION("""COMPUTED_VALUE"""),60.0) -> 60
A6: =IFERROR(__xludf.DUMMYFUNCTION("""COMPUTED_VALUE"""),"(s)-กุ้งแก้ว-51/60-1kg") -> (s)-กุ้งแก้ว-51/60-1kg | B6: =IFERROR(__xludf.DUMMYFUNCTION("""COMPUTED_VALUE"""),10066.0) -> 10066 | C6: =IFERROR(__xludf.DUMMYFUNCTION("""COMPUTED_VALUE"""),"(S) กุ้งแก้ว 51/60 ถุง1Kg") -> (S) กุ้งแก้ว 51/60 ถุง1Kg | F6: =IFERROR(__xludf.DUMMYFUNCTION("""COMPUTED_VALUE"""),"N") -> N | O6: =IFERROR(__xludf.DUMMYFUNCTION("""COMPUTED_VALUE"""),10000.0) -> 10000 | P6: =IFERROR(__xludf.DUMMYFUNCTION("""COMPUTED_VALUE"""),0.1) -> 0.1 | Q6: =IFERROR(__xludf.DUMMYFUNCTION("""COMPUTED_VALUE"""),"N") -> N | R6: =IFERROR(__xludf.DUMMYFUNCTION("""COMPUTED_VALUE"""),"N") -> N | U6: =IFERROR(__xludf.DUMMYFUNCTION("""COMPUTED_VALUE"""),"Y") -> Y | V6: =IFERROR(__xludf.DUMMYFUNCTION("""COMPUTED_VALUE"""),140.0) -> 140
A7: =IFERROR(__xludf.DUMMYFUNCTION("""COMPUTED_VALUE"""),"คอเอ็นแก้ว-แพ็ค1-กก") -> คอเอ็นแก้ว-แพ็ค1-กก | B7: =IFERROR(__xludf.DUMMYFUNCTION("""COMPUTED_VALUE"""),10943.0) -> 10943 | C7: =IFERROR(__xludf.DUMMYFUNCTION("""COMPUTED_VALUE"""),"(S) คอเอ็นแก้ว แพ็ค1 กก") -> (S) คอเอ็นแก้ว แพ็ค1 กก | D7: =IFERROR(__xludf.DUMMYFUNCTION("""COMPUTED_VALUE"""),"**ลัง มหาชัย") -> **ลัง มหาชัย | E7: =IFERROR(__xludf.DUMMYFUNCTION("""COMPUTED_VALUE"""),"<p>1</p>") -> <p>1</p> | F7: =IFERROR(__xludf.DUMMYFUNCTION("""COMPUTED_VALUE"""),"N") -> N | M7: =IFERROR(__xludf.DUMMYFUNCTION("""COMPUTED_VALUE"""),26.1) -> 26.1 | N7: =IFERROR(__xludf.DUMMYFUNCTION("""COMPUTED_VALUE"""),10943.0) -> 10943 | Q7: =IFERROR(__xludf.DUMMYFUNCTION("""COMPUTED_VALUE"""),"Y") -> Y | S7: =IFERROR(__xludf.DUMMYFUNCTION("""COMPUTED_VALUE"""),"ขึ้นของมหาชัย") -> ขึ้นของมหาชัย | T7: =IFERROR(__xludf.DUMMYFUNCTION("""COMPUTED_VALUE"""),26.0) -> 26 | U7: =IFERROR(__xludf.DUMMYFUNCTION("""COMPUTED_VALUE"""),"Y") -> Y | V7: =IFERROR(__xludf.DUMMYFUNCTION("""COMPUTED_VALUE"""),45.0) -> 45 | W7: =IFERROR(__xludf.DUMMYFUNCTION("""COMPUTED_VALUE"""),30.0) -> 30 | X7: =IFERROR(__xludf.DUMMYFUNCTION("""COMPUTED_VALUE"""),10.0) -> 10 | Y7: =IFERROR(__xludf.DUMMYFUNCTION("""COMPUTED_VALUE"""),60.0) -> 60
A8: =IFERROR(__xludf.DUMMYFUNCTION("""COMPUTED_VALUE"""),"(s)-คานิจัง-ยาว500g") -> (s)-คานิจัง-ยาว500g | B8: =IFERROR(__xludf.DUMMYFUNCTION("""COMPUTED_VALUE"""),31226.0) -> 31226 | C8: =IFERROR(__xludf.DUMMYFUNCTION("""COMPUTED_VALUE"""),"(s) คานิจัง ยาว500g") -> (s) คานิจัง ยาว500g | E8: =IFERROR(__xludf.DUMMYFUNCTION("""COMPUTED_VALUE"""),"<p>X</p>") -> <p>X</p> | F8: =IFERROR(__xludf.DUMMYFUNCTION("""COMPUTED_VALUE"""),"N") -> N | N8: =IFERROR(__xludf.DUMMYFUNCTION("""COMPUTED_VALUE"""),8.850016084899E12) -> 8850016084899 | O8: =IFERROR(__xludf.DUMMYFUNCTION("""COMPUTED_VALUE"""),11226.0) -> 11226 | P8: =IFERROR(__xludf.DUMMYFUNCTION("""COMPUTED_VALUE"""),0.05) -> 0.05 | Q8: =IFERROR(__xludf.DUMMYFUNCTION("""COMPUTED_VALUE"""),"N") -> N | R8: =IFERROR(__xludf.DUMMYFUNCTION("""COMPUTED_VALUE"""),"N") -> N | U8: =IFERROR(__xludf.DUMMYFUNCTION("""COMPUTED_VALUE"""),"Y") -> Y | V8: =IFERROR(__xludf.DUMMYFUNCTION("""COMPUTED_VALUE"""),55.0) -> 55
A9: =IFERROR(__xludf.DUMMYFUNCTION("""COMPUTED_VALUE"""),"(s)-ซาลาเปาไข่กุ้ง-แพ็ค-500g") -> (s)-ซาลาเปาไข่กุ้ง-แพ็ค-500g | B9: =IFERROR(__xludf.DUMMYFUNCTION("""COMPUTED_VALUE"""),30981.0) -> 30981 | C9: =IFERROR(__xludf.DUMMYFUNCTION("""COMPUTED_VALUE"""),"(s) ซาลาเปาปลาไข่กุ้ง แพ็ค 500g") -> (s) ซาลาเปาปลาไข่กุ้ง แพ็ค 500g | E9: =IFERROR(__xludf.DUMMYFUNCTION("""COMPUTED_VALUE"""),"X") -> X | F9: =IFERROR(__xludf.DUMMYFUNCTION("""COMPUTED_VALUE"""),"N") -> N | O9: =IFERROR(__xludf.DUMMYFUNCTION("""COMPUTED_VALUE"""),10981.0) -> 10981 | P9: =IFERROR(__xludf.DUMMYFUNCTION("""COMPUTED_VALUE"""),1.0) -> 1 | Q9: =IFERROR(__xludf.DUMMYFUNCTION("""COMPUTED_VALUE"""),"N") -> N | R9: =IFERROR(__xludf.DUMMYFUNCTION("""COMPUTED_VALUE"""),"N") -> N | U9: =IFERROR(__xludf.DUMMYFUNCTION("""COMPUTED_VALUE"""),"Y") -> Y | V9: =IFERROR(__xludf.DUMMYFUNCTION("""COMPUTED_VALUE"""),85.0) -> 85
A10: =IFERROR(__xludf.DUMMYFUNCTION("""COMPUTED_VALUE"""),"(s)-ซาลาเปาไส้ไข่เค็ม-500g") -> (s)-ซาลาเปาไส้ไข่เค็ม-500g | B10: =IFERROR(__xludf.DUMMYFUNCTION("""COMPUTED_VALUE"""),30675.0) -> 30675 | C10: =IFERROR(__xludf.DUMMYFUNCTION("""COMPUTED_VALUE"""),"(s) ซาลาเปาไส้ไข่เค็ม 500g") -> (s) ซาลาเปาไส้ไข่เค็ม 500g | E10: =IFERROR(__xludf.DUMMYFUNCTION("""COMPUTED_VALUE"""),"<p>X</p>") -> <p>X</p> | F10: =IFERROR(__xludf.DUMMYFUNCTION("""COMPUTED_VALUE"""),"N") -> N | N10: =IFERROR(__xludf.DUMMYFUNCTION("""COMPUTED_VALUE"""),8.850016635152E12) -> 8850016635152 | O10: =IFERROR(__xludf.DUMMYFUNCTION("""COMPUTED_VALUE"""),10675.0) -> 10675 | P10: =IFERROR(__xludf.DUMMYFUNCTION("""COMPUTED_VALUE"""),1.0) -> 1 | Q10: =IFERROR(__xludf.DUMMYFUNCTION("""COMPUTED_VALUE"""),"N") -> N | R10: =IFERROR(__xludf.DUMMYFUNCTION("""COMPUTED_VALUE"""),"N") -> N | U10: =IFERROR(__xludf.DUMMYFUNCTION("""COMPUTED_VALUE"""),"N") -> N | V10: =IFERROR(__xludf.DUMMYFUNCTION("""COMPUTED_VALUE"""),89.0) -> 89
A11: =IFERROR(__xludf.DUMMYFUNCTION("""COMPUTED_VALUE"""),"(s)-ซูเปอร์-อลาสก้า-250g") -> (s)-ซูเปอร์-อลาสก้า-250g | B11: =IFERROR(__xludf.DUMMYFUNCTION("""COMPUTED_VALUE"""),31490.0) -> 31490 | C11: =IFERROR(__xludf.DUMMYFUNCTION("""COMPUTED_VALUE"""),"(s) ซูเปอร์ อลาสก้า 250g") -> (s) ซูเปอร์ อลาสก้า 250g | E11: =IFERROR(__xludf.DUMMYFUNCTION("""COMPUTED_VALUE"""),"X") -> X | F11: =IFERROR(__xludf.DUMMYFUNCTION("""COMPUTED_VALUE"""),"N") -> N | N11: =IFERROR(__xludf.DUMMYFUNCTION("""COMPUTED_VALUE"""),8.850016635794E12) -> 8850016635794 | O11: =IFERROR(__xludf.DUMMYFUNCTION("""COMPUTED_VALUE"""),11490.0) -> 11490 | P11: =IFERROR(__xludf.DUMMYFUNCTION("""COMPUTED_VALUE"""),1.0) -> 1 | Q11: =IFERROR(__xludf.DUMMYFUNCTION("""COMPUTED_VALUE"""),"N") -> N | R11: =IFERROR(__xludf.DUMMYFUNCTION("""COMPUTED_VALUE"""),"N") -> N | U11: =IFERROR(__xludf.DUMMYFUNCTION("""COMPUTED_VALUE"""),"Y") -> Y | V11: =IFERROR(__xludf.DUMMYFUNCTION("""COMPUTED_VALUE"""),60.0) -> 60
A12: =IFERROR(__xludf.DUMMYFUNCTION("""COMPUTED_VALUE"""),"ดอลลี่หั่น-(ลังน้ําตาล)-1kg") -> ดอลลี่หั่น-(ลังน้ําตาล)-1kg | B12: =IFERROR(__xludf.DUMMYFUNCTION("""COMPUTED_VALUE"""),10048.0) -> 10048 | C12: =IFERROR(__xludf.DUMMYFUNCTION("""COMPUTED_VALUE"""),"(S) ดอลลี่หั่น (น้ำตาล) 1kg") -> (S) ดอลลี่หั่น (น้ำตาล) 1kg | F12: =IFERROR(__xludf.DUMMYFUNCTION("""COMPUTED_VALUE"""),"N") -> N | O12: =IFERROR(__xludf.DUMMYFUNCTION("""COMPUTED_VALUE"""),10472.0) -> 10472 | P12: =IFERROR(__xludf.DUMMYFUNCTION("""COMPUTED_VALUE"""),0.1) -> 0.1 | Q12: =IFERROR(__xludf.DUMMYFUNCTION("""COMPUTED_VALUE"""),"N") -> N | R12: =IFERROR(__xludf.DUMMYFUNCTION("""COMPUTED_VALUE"""),"N") -> N | U12: =IFERROR(__xludf.DUMMYFUNCTION("""COMPUTED_VALUE"""),"Y") -> Y | V12: =IFERROR(__xludf.DUMMYFUNCTION("""COMPUTED_VALUE"""),70.0) -> 70
A13: =IFERROR(__xludf.DUMMYFUNCTION("""COMPUTED_VALUE"""),"ตะเกียบ-ตราฟินิกซ์-1ห่อ-1") -> ตะเกียบ-ตราฟินิกซ์-1ห่อ-1 | B13: =IFERROR(__xludf.DUMMYFUNCTION("""COMPUTED_VALUE"""),10134.0) -> 10134 | C13: =IFERROR(__xludf.DUMMYFUNCTION("""COMPUTED_VALUE"""),"(S) ตะเกียบ ท.พิพัฒน์") -> (S) ตะเกียบ ท.พิพัฒน์ | E13: =IFERROR(__xludf.DUMMYFUNCTION("""COMPUTED_VALUE"""),"<p>X</p>") -> <p>X</p> | F13: =IFERROR(__xludf.DUMMYFUNCTION("""COMPUTED_VALUE"""),"N") -> N | N13: =IFERROR(__xludf.DUMMYFUNCTION("""COMPUTED_VALUE"""),8.85712659513E12) -> 8857126595130 | O13: =IFERROR(__xludf.DUMMYFUNCTION("""COMPUTED_VALUE"""),10837.0) -> 10837 | P13: =IFERROR(__xludf.DUMMYFUNCTION("""COMPUTED_VALUE"""),0.025) -> 0.025 | Q13: =IFERROR(__xludf.DUMMYFUNCTION("""COMPUTED_VALUE"""),"N") -> N | R13: =IFERROR(__xludf.DUMMYFUNCTION("""COMPUTED_VALUE"""),"N") -> N | U13: =IFERROR(__xludf.DUMMYFUNCTION("""COMPUTED_VALUE"""),"Y") -> Y | V13: =IFERROR(__xludf.DUMMYFUNCTION("""COMPUTED_VALUE"""),20.0) -> 20
A14: =IFERROR(__xludf.DUMMYFUNCTION("""COMPUTED_VALUE"""),"ถงขุ่น9*14") -> ถงขุ่น9*14 | B14: =IFERROR(__xludf.DUMMYFUNCTION("""COMPUTED_VALUE"""),11558.0) -> 11558 | C14: =IFERROR(__xludf.DUMMYFUNCTION("""COMPUTED_VALUE"""),"(S) ถงขุ่น9*14") -> (S) ถงขุ่น9*14 | E14: =IFERROR(__xludf.DUMMYFUNCTION("""COMPUTED_VALUE"""),"X") -> X | F14: =IFERROR(__xludf.DUMMYFUNCTION("""COMPUTED_VALUE"""),"N") -> N | M14: =IFERROR(__xludf.DUMMYFUNCTION("""COMPUTED_VALUE"""),40.0) -> 40 | Q14: =IFERROR(__xludf.DUMMYFUNCTION("""COMPUTED_VALUE"""),"N") -> N | U14: =IFERROR(__xludf.DUMMYFUNCTION("""COMPUTED_VALUE"""),"Y") -> Y | V14: =IFERROR(__xludf.DUMMYFUNCTION("""COMPUTED_VALUE"""),45.0) -> 45
A15: =IFERROR(__xludf.DUMMYFUNCTION("""COMPUTED_VALUE"""),"ถุง-8*16-ตรานางกวัก-แพ็ค-1") -> ถุง-8*16-ตรานางกวัก-แพ็ค-1 | B15: =IFERROR(__xludf.DUMMYFUNCTION("""COMPUTED_VALUE"""),20150.0) -> 20150 | C15: =IFERROR(__xludf.DUMMYFUNCTION("""COMPUTED_VALUE"""),"(S) ถุง 10*15 pp") -> (S) ถุง 10*15 pp | D15: =IFERROR(__xludf.DUMMYFUNCTION("""COMPUTED_VALUE"""),"**ของแห้ง") -> **ของแห้ง | E15: =IFERROR(__xludf.DUMMYFUNCTION("""COMPUTED_VALUE"""),"X") -> X | F15: =IFERROR(__xludf.DUMMYFUNCTION("""COMPUTED_VALUE"""),"N") -> N | M15: =IFERROR(__xludf.DUMMYFUNCTION("""COMPUTED_VALUE"""),36.0) -> 36 | N15: =IFERROR(__xludf.DUMMYFUNCTION("""COMPUTED_VALUE"""),8.858817011243E12) -> 8858817011243 | Q15: =IFERROR(__xludf.DUMMYFUNCTION("""COMPUTED_VALUE"""),"Y") -> Y | T15: =IFERROR(__xludf.DUMMYFUNCTION("""COMPUTED_VALUE"""),0.0) -> 0 | U15: =IFERROR(__xludf.DUMMYFUNCTION("""COMPUTED_VALUE"""),"Y") -> Y | V15: =IFERROR(__xludf.DUMMYFUNCTION("""COMPUTED_VALUE"""),45.0) -> 45 | W15: =IFERROR(__xludf.DUMMYFUNCTION("""COMPUTED_VALUE"""),33.0) -> 33
A16: =IFERROR(__xludf.DUMMYFUNCTION("""COMPUTED_VALUE"""),"ถุง-12*20-ตรานางกวัก-แพ็ค-1") -> ถุง-12*20-ตรานางกวัก-แพ็ค-1 | B16: =IFERROR(__xludf.DUMMYFUNCTION("""COMPUTED_VALUE"""),20138.0) -> 20138 | C16: =IFERROR(__xludf.DUMMYFUNCTION("""COMPUTED_VALUE"""),"(S) ถุง 12*20 ตรางาช้าง") -> (S) ถุง 12*20 ตรางาช้าง | D16: =IFERROR(__xludf.DUMMYFUNCTION("""COMPUTED_VALUE"""),"**ของแห้ง") -> **ของแห้ง | E16: =IFERROR(__xludf.DUMMYFUNCTION("""COMPUTED_VALUE"""),"<p>X</p>") -> <p>X</p> | F16: =IFERROR(__xludf.DUMMYFUNCTION("""COMPUTED_VALUE"""),"N") -> N | M16: =IFERROR(__xludf.DUMMYFUNCTION("""COMPUTED_VALUE"""),41.0) -> 41 | N16: =IFERROR(__xludf.DUMMYFUNCTION("""COMPUTED_VALUE"""),8.858817019652E12) -> 8858817019652 | Q16: =IFERROR(__xludf.DUMMYFUNCTION("""COMPUTED_VALUE"""),"Y") -> Y | T16: =IFERROR(__xludf.DUMMYFUNCTION("""COMPUTED_VALUE"""),41.0) -> 41 | U16: =IFERROR(__xludf.DUMMYFUNCTION("""COMPUTED_VALUE"""),"Y") -> Y | V16: =IFERROR(__xludf.DUMMYFUNCTION("""COMPUTED_VALUE"""),45.0) -> 45 | W16: =IFERROR(__xludf.DUMMYFUNCTION("""COMPUTED_VALUE"""),30.0) -> 30 | X16: =IFERROR(__xludf.DUMMYFUNCTION("""COMPUTED_VALUE"""),4.0) -> 4
A17: =IFERROR(__xludf.DUMMYFUNCTION("""COMPUTED_VALUE"""),"ถุง-6*9") -> ถุง-6*9 | B17: =IFERROR(__xludf.DUMMYFUNCTION("""COMPUTED_VALUE"""),10694.0) -> 10694 | C17: =IFERROR(__xludf.DUMMYFUNCTION("""COMPUTED_VALUE"""),"(S) ถุง 6*9pp ฟ้า") -> (S) ถุง 6*9pp ฟ้า | D17: =IFERROR(__xludf.DUMMYFUNCTION("""COMPUTED_VALUE"""),"**ของแห้ง") -> **ของแห้ง | E17: =IFERROR(__xludf.DUMMYFUNCTION("""COMPUTED_VALUE"""),"X") -> X | F17: =IFERROR(__xludf.DUMMYFUNCTION("""COMPUTED_VALUE"""),"N") -> N | M17: =IFERROR(__xludf.DUMMYFUNCTION("""COMPUTED_VALUE"""),36.0) -> 36 | N17: =IFERROR(__xludf.DUMMYFUNCTION("""COMPUTED_VALUE"""),8.858817011151E12) -> 8858817011151 | Q17: =IFERROR(__xludf.DUMMYFUNCTION("""COMPUTED_VALUE"""),"Y") -> Y | T17: =IFERROR(__xludf.DUMMYFUNCTION("""COMPUTED_VALUE"""),0.0) -> 0 | U17: =IFERROR(__xludf.DUMMYFUNCTION("""COMPUTED_VALUE"""),"Y") -> Y | V17: =IFERROR(__xludf.DUMMYFUNCTION("""COMPUTED_VALUE"""),45.0) -> 45 | W17: =IFERROR(__xludf.DUMMYFUNCTION("""COMPUTED_VALUE"""),12.0) -> 12
A18: =IFERROR(__xludf.DUMMYFUNCTION("""COMPUTED_VALUE"""),"ถุง-20*30-ตรานางกวัก-แพ็ค-1") -> ถุง-20*30-ตรานางกวัก-แพ็ค-1 | B18: =IFERROR(__xludf.DUMMYFUNCTION("""COMPUTED_VALUE"""),20139.0) -> 20139 | C18: =IFERROR(__xludf.DUMMYFUNCTION("""COMPUTED_VALUE"""),"(S) ถุง 7*11 ppม่วง") -> (S) ถุง 7*11 ppม่วง | D18: =IFERROR(__xludf.DUMMYFUNCTION("""COMPUTED_VALUE"""),"**ของแห้ง") -> **ของแห้ง | E18: =IFERROR(__xludf.DUMMYFUNCTION("""COMPUTED_VALUE"""),"<p>X</p>") -> <p>X</p> | F18: =IFERROR(__xludf.DUMMYFUNCTION("""COMPUTED_VALUE"""),"N") -> N | M18: =IFERROR(__xludf.DUMMYFUNCTION("""COMPUTED_VALUE"""),46.0) -> 46 | N18: =IFERROR(__xludf.DUMMYFUNCTION("""COMPUTED_VALUE"""),8.858817011199E12) -> 8858817011199 | Q18: =IFERROR(__xludf.DUMMYFUNCTION("""COMPUTED_VALUE"""),"Y") -> Y | T18: =IFERROR(__xludf.DUMMYFUNCTION("""COMPUTED_VALUE"""),46.0) -> 46 | U18: =IFERROR(__xludf.DUMMYFUNCTION("""COMPUTED_VALUE"""),"Y") -> Y | V18: =IFERROR(__xludf.DUMMYFUNCTION("""COMPUTED_VALUE"""),55.0) -> 55 | W18: =IFERROR(__xludf.DUMMYFUNCTION("""COMPUTED_VALUE"""),40.0) -> 40
A19: =IFERROR(__xludf.DUMMYFUNCTION("""COMPUTED_VALUE"""),"8*12-หนา") -> 8*12-หนา | B19: =IFERROR(__xludf.DUMMYFUNCTION("""COMPUTED_VALUE"""),11351.0) -> 11351 | C19: =IFERROR(__xludf.DUMMYFUNCTION("""COMPUTED_VALUE"""),"(S) ถุง 8*12 ขุ่น") -> (S) ถุง 8*12 ขุ่น | D19: =IFERROR(__xludf.DUMMYFUNCTION("""COMPUTED_VALUE"""),"**ของแห้ง") -> **ของแห้ง | E19: =IFERROR(__xludf.DUMMYFUNCTION("""COMPUTED_VALUE"""),"X") -> X | F19: =IFERROR(__xludf.DUMMYFUNCTION("""COMPUTED_VALUE"""),"N") -> N | M19: =IFERROR(__xludf.DUMMYFUNCTION("""COMPUTED_VALUE"""),36.0) -> 36 | N19: =IFERROR(__xludf.DUMMYFUNCTION("""COMPUTED_VALUE"""),8.858817012264E12) -> 8858817012264 | Q19: =IFERROR(__xludf.DUMMYFUNCTION("""COMPUTED_VALUE"""),"Y") -> Y | T19: =IFERROR(__xludf.DUMMYFUNCTION("""COMPUTED_VALUE"""),0.0) -> 0 | U19: =IFERROR(__xludf.DUMMYFUNCTION("""COMPUTED_VALUE"""),"Y") -> Y | V19: =IFERROR(__xludf.DUMMYFUNCTION("""COMPUTED_VALUE"""),45.0) -> 45 | W19: =IFERROR(__xludf.DUMMYFUNCTION("""COMPUTED_VALUE"""),4.0) -> 4
A20: =IFERROR(__xludf.DUMMYFUNCTION("""COMPUTED_VALUE"""),"ถุง-9*14ppน้ำตาลเข้ม") -> ถุง-9*14ppน้ำตาลเข้ม | B20: =IFERROR(__xludf.DUMMYFUNCTION("""COMPUTED_VALUE"""),10695.0) -> 10695 | C20: =IFERROR(__xludf.DUMMYFUNCTION("""COMPUTED_VALUE"""),"(S) ถุง 9*14pp") -> (S) ถุง 9*14pp | D20: =IFERROR(__xludf.DUMMYFUNCTION("""COMPUTED_VALUE"""),"**ของแห้ง") -> **ของแห้ง | E20: =IFERROR(__xludf.DUMMYFUNCTION("""COMPUTED_VALUE"""),"<p>X</p>") -> <p>X</p> | F20: =IFERROR(__xludf.DUMMYFUNCTION("""COMPUTED_VALUE"""),"N") -> N | M20: =IFERROR(__xludf.DUMMYFUNCTION("""COMPUTED_VALUE"""),43.0) -> 43 | N20: =IFERROR(__xludf.DUMMYFUNCTION("""COMPUTED_VALUE"""),8.858817011236E12) -> 8858817011236 | Q20: =IFERROR(__xludf.DUMMYFUNCTION("""COMPUTED_VALUE"""),"Y") -> Y | T20: =IFERROR(__xludf.DUMMYFUNCTION("""COMPUTED_VALUE"""),0.0) -> 0 | U20: =IFERROR(__xludf.DUMMYFUNCTION("""COMPUTED_VALUE"""),"Y") -> Y | V20: =IFERROR(__xludf.DUMMYFUNCTION("""COMPUTED_VALUE"""),45.0) -> 45 | W20: =IFERROR(__xludf.DUMMYFUNCTION("""COMPUTED_VALUE"""),5.0) -> 5 | X20: =IFERROR(__xludf.DUMMYFUNCTION("""COMPUTED_VALUE"""),0.0) -> 0
A21: =IFERROR(__xludf.DUMMYFUNCTION("""COMPUTED_VALUE"""),"ถุง-9*18-ตรางาช้าง") -> ถุง-9*18-ตรางาช้าง | B21: =IFERROR(__xludf.DUMMYFUNCTION("""COMPUTED_VALUE"""),11151.0) -> 11151 | C21: =IFERROR(__xludf.DUMMYFUNCTION("""COMPUTED_VALUE"""),"(S) ถุง 9*18 ตรางาช้าง") -> (S) ถุง 9*18 ตรางาช้าง | D21: =IFERROR(__xludf.DUMMYFUNCTION("""COMPUTED_VALUE"""),"**ของแห้ง") -> **ของแห้ง | E21: =IFERROR(__xludf.DUMMYFUNCTION("""COMPUTED_VALUE"""),"X") -> X | F21: =IFERROR(__xludf.DUMMYFUNCTION("""COMPUTED_VALUE"""),"N") -> N | M21: =IFERROR(__xludf.DUMMYFUNCTION("""COMPUTED_VALUE"""),36.0) -> 36 | N21: =IFERROR(__xludf.DUMMYFUNCTION("""COMPUTED_VALUE"""),8.858817019645E12) -> 8858817019645 | Q21: =IFERROR(__xludf.DUMMYFUNCTION("""COMPUTED_VALUE"""),"Y") -> Y | T21: =IFERROR(__xludf.DUMMYFUNCTION("""COMPUTED_VALUE"""),0.0) -> 0 | U21: =IFERROR(__xludf.DUMMYFUNCTION("""COMPUTED_VALUE"""),"Y") -> Y | V21: =IFERROR(__xludf.DUMMYFUNCTION("""COMPUTED_VALUE"""),45.0) -> 45 | W21: =IFERROR(__xludf.DUMMYFUNCTION("""COMPUTED_VALUE"""),5.0) -> 5
A22: =IFERROR(__xludf.DUMMYFUNCTION("""COMPUTED_VALUE"""),"ถุง-นางกวัก-8*15-แพ็ค") -> ถุง-นางกวัก-8*15-แพ็ค | B22: =IFERROR(__xludf.DUMMYFUNCTION("""COMPUTED_VALUE"""),10473.0) -> 10473 | C22: =IFERROR(__xludf.DUMMYFUNCTION("""COMPUTED_VALUE"""),"(S) ถุง นางกวัก 8*15 แพ็ค") -> (S) ถุง นางกวัก 8*15 แพ็ค | D22: =IFERROR(__xludf.DUMMYFUNCTION("""COMPUTED_VALUE"""),"**ของแห้ง") -> **ของแห้ง | E22: =IFERROR(__xludf.DUMMYFUNCTION("""COMPUTED_VALUE"""),"X") -> X | F22: =IFERROR(__xludf.DUMMYFUNCTION("""COMPUTED_VALUE"""),"N") -> N | M22: =IFERROR(__xludf.DUMMYFUNCTION("""COMPUTED_VALUE"""),22.0) -> 22 | N22: =IFERROR(__xludf.DUMMYFUNCTION("""COMPUTED_VALUE"""),8.859052000047E12) -> 8859052000047 | Q22: =IFERROR(__xludf.DUMMYFUNCTION("""COMPUTED_VALUE"""),"Y") -> Y | T22: =IFERROR(__xludf.DUMMYFUNCTION("""COMPUTED_VALUE"""),0.0) -> 0 | U22: =IFERROR(__xludf.DUMMYFUNCTION("""COMPUTED_VALUE"""),"Y") -> Y | V22: =IFERROR(__xludf.DUMMYFUNCTION("""COMPUTED_VALUE"""),25.0) -> 25 | W22: =IFERROR(__xludf.DUMMYFUNCTION("""COMPUTED_VALUE"""),20.0) -> 20
A23: =IFERROR(__xludf.DUMMYFUNCTION("""COMPUTED_VALUE"""),"ถุง10*15-ขุ่น") -> ถุง10*15-ขุ่น | B23: =IFERROR(__xludf.DUMMYFUNCTION("""COMPUTED_VALUE"""),11583.0) -> 11583 | C23: =IFERROR(__xludf.DUMMYFUNCTION("""COMPUTED_VALUE"""),"(S) ถุง10*15 ขุ่น") -> (S) ถุง10*15 ขุ่น | E23: =IFERROR(__xludf.DUMMYFUNCTION("""COMPUTED_VALUE"""),"X") -> X | F23: =IFERROR(__xludf.DUMMYFUNCTION("""COMPUTED_VALUE"""),"N") -> N | M23: =IFERROR(__xludf.DUMMYFUNCTION("""COMPUTED_VALUE"""),40.0) -> 40 | Q23: =IFERROR(__xludf.DUMMYFUNCTION("""COMPUTED_VALUE"""),"N") -> N | U23: =IFERROR(__xludf.DUMMYFUNCTION("""COMPUTED_VALUE"""),"Y") -> Y | V23: =IFERROR(__xludf.DUMMYFUNCTION("""COMPUTED_VALUE"""),45.0) -> 45
A24: =IFERROR(__xludf.DUMMYFUNCTION("""COMPUTED_VALUE"""),"ถุง9*14ขุ่น") -> ถุง9*14ขุ่น | B24: =IFERROR(__xludf.DUMMYFUNCTION("""COMPUTED_VALUE"""),11559.0) -> 11559 | C24: =IFERROR(__xludf.DUMMYFUNCTION("""COMPUTED_VALUE"""),"(S) ถุง9*14ขุ่น") -> (S) ถุง9*14ขุ่น | D24: =IFERROR(__xludf.DUMMYFUNCTION("""COMPUTED_VALUE"""),"**ของแห้ง") -> **ของแห้ง | E24: =IFERROR(__xludf.DUMMYFUNCTION("""COMPUTED_VALUE"""),"<p>X</p>") -> <p>X</p> | F24: =IFERROR(__xludf.DUMMYFUNCTION("""COMPUTED_VALUE"""),"N") -> N | M24: =IFERROR(__xludf.DUMMYFUNCTION("""COMPUTED_VALUE"""),45.4) -> 45.4 | N24: =IFERROR(__xludf.DUMMYFUNCTION("""COMPUTED_VALUE"""),8.858817012271E12) -> 8858817012271 | Q24: =IFERROR(__xludf.DUMMYFUNCTION("""COMPUTED_VALUE"""),"Y") -> Y | T24: =IFERROR(__xludf.DUMMYFUNCTION("""COMPUTED_VALUE"""),0.0) -> 0 | U24: =IFERROR(__xludf.DUMMYFUNCTION("""COMPUTED_VALUE"""),"Y") -> Y | V24: =IFERROR(__xludf.DUMMYFUNCTION("""COMPUTED_VALUE"""),55.0) -> 55 | W24: =IFERROR(__xludf.DUMMYFUNCTION("""COMPUTED_VALUE"""),50.0) -> 50
A25: =IFERROR(__xludf.DUMMYFUNCTION("""COMPUTED_VALUE"""),"ถุง-16*/26") -> ถุง-16*/26 | B25: =IFERROR(__xludf.DUMMYFUNCTION("""COMPUTED_VALUE"""),11384.0) -> 11384 | C25: =IFERROR(__xludf.DUMMYFUNCTION("""COMPUTED_VALUE"""),"(S) ถุงLL 14*22สีส้ม500g") -> (S) ถุงLL 14*22สีส้ม500g | E25: =IFERROR(__xludf.DUMMYFUNCTION("""COMPUTED_VALUE"""),"<p>X</p>") -> <p>X</p> | F25: =IFERROR(__xludf.DUMMYFUNCTION("""COMPUTED_VALUE"""),"N") -> N | M25: =IFERROR(__xludf.DUMMYFUNCTION("""COMPUTED_VALUE"""),46.0) -> 46 | N25: =IFERROR(__xludf.DUMMYFUNCTION("""COMPUTED_VALUE"""),8.858817012738E12) -> 8858817012738 | Q25: =IFERROR(__xludf.DUMMYFUNCTION("""COMPUTED_VALUE"""),"N") -> N | U25: =IFERROR(__xludf.DUMMYFUNCTION("""COMPUTED_VALUE"""),"Y") -> Y | V25: =IFERROR(__xludf.DUMMYFUNCTION("""COMPUTED_VALUE"""),55.0) -> 55
A26: =IFERROR(__xludf.DUMMYFUNCTION("""COMPUTED_VALUE"""),"ถุงหนา8*16") -> ถุงหนา8*16 | B26: =IFERROR(__xludf.DUMMYFUNCTION("""COMPUTED_VALUE"""),11360.0) -> 11360 | C26: =IFERROR(__xludf.DUMMYFUNCTION("""COMPUTED_VALUE"""),"(S) ถุงหนา8*16") -> (S) ถุงหนา8*16 | E26: =IFERROR(__xludf.DUMMYFUNCTION("""COMPUTED_VALUE"""),"X") -> X | F26: =IFERROR(__xludf.DUMMYFUNCTION("""COMPUTED_VALUE"""),"N") -> N | M26: =IFERROR(__xludf.DUMMYFUNCTION("""COMPUTED_VALUE"""),36.0) -> 36 | N26: =IFERROR(__xludf.DUMMYFUNCTION("""COMPUTED_VALUE"""),8.858817019638E12) -> 8858817019638 | Q26: =IFERROR(__xludf.DUMMYFUNCTION("""COMPUTED_VALUE"""),"N") -> N | U26: =IFERROR(__xludf.DUMMYFUNCTION("""COMPUTED_VALUE"""),"Y") -> Y | V26: =IFERROR(__xludf.DUMMYFUNCTION("""COMPUTED_VALUE"""),45.0) -> 45
A27: =IFERROR(__xludf.DUMMYFUNCTION("""COMPUTED_VALUE"""),"ถุงหูหิ้ว-12*20-แพ็ค") -> ถุงหูหิ้ว-12*20-แพ็ค | B27: =IFERROR(__xludf.DUMMYFUNCTION("""COMPUTED_VALUE"""),10475.0) -> 10475 | C27: =IFERROR(__xludf.DUMMYFUNCTION("""COMPUTED_VALUE"""),"(S) ถุงหิ้ว12*20 ตราส้ม(บาง)") -> (S) ถุงหิ้ว12*20 ตราส้ม(บาง) | D27: =IFERROR(__xludf.DUMMYFUNCTION("""COMPUTED_VALUE"""),"**ของแห้ง") -> **ของแห้ง | E27: =IFERROR(__xludf.DUMMYFUNCTION("""COMPUTED_VALUE"""),"<p>X</p>") -> <p>X</p> | F27: =IFERROR(__xludf.DUMMYFUNCTION("""COMPUTED_VALUE"""),"N") -> N | M27: =IFERROR(__xludf.DUMMYFUNCTION("""COMPUTED_VALUE"""),36.29) -> 36.29 | N27: =IFERROR(__xludf.DUMMYFUNCTION("""COMPUTED_VALUE"""),8.858678310059E12) -> 8858678310059 | Q27: =IFERROR(__xludf.DUMMYFUNCTION("""COMPUTED_VALUE"""),"Y") -> Y | T27: =IFERROR(__xludf.DUMMYFUNCTION("""COMPUTED_VALUE"""),36.29) -> 36.29 | U27: =IFERROR(__xludf.DUMMYFUNCTION("""COMPUTED_VALUE"""),"Y") -> Y | V27: =IFERROR(__xludf.DUMMYFUNCTION("""COMPUTED_VALUE"""),45.0) -> 45 | W27: =IFERROR(__xludf.DUMMYFUNCTION("""COMPUTED_VALUE"""),61.0) -> 61 | X27: =IFERROR(__xludf.DUMMYFUNCTION("""COMPUTED_VALUE"""),0.0) -> 0
A28: =IFERROR(__xludf.DUMMYFUNCTION("""COMPUTED_VALUE"""),"ถุงหูหิ้ว-6*14") -> ถุงหูหิ้ว-6*14 | B28: =IFERROR(__xludf.DUMMYFUNCTION("""COMPUTED_VALUE"""),10497.0) -> 10497 | C28: =IFERROR(__xludf.DUMMYFUNCTION("""COMPUTED_VALUE"""),"(S) ถุงหูหิ้ว 6*14มิสแฮปปี้") -> (S) ถุงหูหิ้ว 6*14มิสแฮปปี้ | D28: =IFERROR(__xludf.DUMMYFUNCTION("""COMPUTED_VALUE"""),"**ของแห้ง") -> **ของแห้ง | E28: =IFERROR(__xludf.DUMMYFUNCTION("""COMPUTED_VALUE"""),"X") -> X | F28: =IFERROR(__xludf.DUMMYFUNCTION("""COMPUTED_VALUE"""),"N") -> N | M28: =IFERROR(__xludf.DUMMYFUNCTION("""COMPUTED_VALUE"""),10.0) -> 10 | N28: =IFERROR(__xludf.DUMMYFUNCTION("""COMPUTED_VALUE"""),8.858746105396E12) -> 8858746105396 | Q28: =IFERROR(__xludf.DUMMYFUNCTION("""COMPUTED_VALUE"""),"Y") -> Y | T28: =IFERROR(__xludf.DUMMYFUNCTION("""COMPUTED_VALUE"""),0.0) -> 0 | U28: =IFERROR(__xludf.DUMMYFUNCTION("""COMPUTED_VALUE"""),"Y") -> Y | V28: =IFERROR(__xludf.DUMMYFUNCTION("""COMPUTED_VALUE"""),15.0) -> 15 | W28: =IFERROR(__xludf.DUMMYFUNCTION("""COMPUTED_VALUE"""),1.0) -> 1
A29: =IFERROR(__xludf.DUMMYFUNCTION("""COMPUTED_VALUE"""),"ถุงหูหิ้ว-7*15") -> ถุงหูหิ้ว-7*15 | B29: =IFERROR(__xludf.DUMMYFUNCTION("""COMPUTED_VALUE"""),10495.0) -> 10495 | C29: =IFERROR(__xludf.DUMMYFUNCTION("""COMPUTED_VALUE"""),"(S) ถุงหูหิ้ว 7*15ตราส้ม") -> (S) ถุงหูหิ้ว 7*15ตราส้ม | D29: =IFERROR(__xludf.DUMMYFUNCTION("""COMPUTED_VALUE"""),"**ของแห้ง") -> **ของแห้ง | E29: =IFERROR(__xludf.DUMMYFUNCTION("""COMPUTED_VALUE"""),"X") -> X | F29: =IFERROR(__xludf.DUMMYFUNCTION("""COMPUTED_VALUE"""),"N") -> N | M29: =IFERROR(__xludf.DUMMYFUNCTION("""COMPUTED_VALUE"""),10.5) -> 10.5 | N29: =IFERROR(__xludf.DUMMYFUNCTION("""COMPUTED_VALUE"""),8.858678310066E12) -> 8858678310066 | Q29: =IFERROR(__xludf.DUMMYFUNCTION("""COMPUTED_VALUE"""),"Y") -> Y | T29: =IFERROR(__xludf.DUMMYFUNCTION("""COMPUTED_VALUE"""),0.0) -> 0 | U29: =IFERROR(__xludf.DUMMYFUNCTION("""COMPUTED_VALUE"""),"Y") -> Y | V29: =IFERROR(__xludf.DUMMYFUNCTION("""COMPUTED_VALUE"""),15.0) -> 15 | W29: =IFERROR(__xludf.DUMMYFUNCTION("""COMPUTED_VALUE"""),3.0) -> 3
A30: =IFERROR(__xludf.DUMMYFUNCTION("""COMPUTED_VALUE"""),"ถุงหูหิ้ว-7*15ตราเด็ก") -> ถุงหูหิ้ว-7*15ตราเด็ก | B30: =IFERROR(__xludf.DUMMYFUNCTION("""COMPUTED_VALUE"""),11011.0) -> 11011 | C30: =IFERROR(__xludf.DUMMYFUNCTION("""COMPUTED_VALUE"""),"(S) ถุงหูหิ้ว 7*15ตราเด็ก") -> (S) ถุงหูหิ้ว 7*15ตราเด็ก | D30: =IFERROR(__xludf.DUMMYFUNCTION("""COMPUTED_VALUE"""),"**ของแห้ง") -> **ของแห้ง | E30: =IFERROR(__xludf.DUMMYFUNCTION("""COMPUTED_VALUE"""),"X") -> X | F30: =IFERROR(__xludf.DUMMYFUNCTION("""COMPUTED_VALUE"""),"N") -> N | M30: =IFERROR(__xludf.DUMMYFUNCTION("""COMPUTED_VALUE"""),22.0) -> 22 | N30: =IFERROR(__xludf.DUMMYFUNCTION("""COMPUTED_VALUE"""),8.8588711119282E13) -> 88588711119282 | Q30: =IFERROR(__xludf.DUMMYFUNCTION("""COMPUTED_VALUE"""),"Y") -> Y | T30: =IFERROR(__xludf.DUMMYFUNCTION("""COMPUTED_VALUE"""),0.0) -> 0 | U30: =IFERROR(__xludf.DUMMYFUNCTION("""COMPUTED_VALUE"""),"Y") -> Y | V30: =IFERROR(__xludf.DUMMYFUNCTION("""COMPUTED_VALUE"""),27.0) -> 27 | W30: =IFERROR(__xludf.DUMMYFUNCTION("""COMPUTED_VALUE"""),1.0) -> 1
A31: =IFERROR(__xludf.DUMMYFUNCTION("""COMPUTED_VALUE"""),"ถุงหูหิ้ว-9*18--ตราเด็ก") -> ถุงหูหิ้ว-9*18--ตราเด็ก | B31: =IFERROR(__xludf.DUMMYFUNCTION("""COMPUTED_VALUE"""),11012.0) -> 11012 | C31: =IFERROR(__xludf.DUMMYFUNCTION("""COMPUTED_VALUE"""),"(S) ถุงหูหิ้ว 9*18 ตรามิสแฮปปี้") -> (S) ถุงหูหิ้ว 9*18 ตรามิสแฮปปี้ | D31: =IFERROR(__xludf.DUMMYFUNCTION("""COMPUTED_VALUE"""),"**ของแห้ง") -> **ของแห้ง | E31: =IFERROR(__xludf.DUMMYFUNCTION("""COMPUTED_VALUE"""),"X") -> X | F31: =IFERROR(__xludf.DUMMYFUNCTION("""COMPUTED_VALUE"""),"N") -> N | M31: =IFERROR(__xludf.DUMMYFUNCTION("""COMPUTED_VALUE"""),22.0) -> 22 | N31: =IFERROR(__xludf.DUMMYFUNCTION("""COMPUTED_VALUE"""),8.858746105419E12) -> 8858746105419 | Q31: =IFERROR(__xludf.DUMMYFUNCTION("""COMPUTED_VALUE"""),"Y") -> Y | T31: =IFERROR(__xludf.DUMMYFUNCTION("""COMPUTED_VALUE"""),0.0) -> 0 | U31: =IFERROR(__xludf.DUMMYFUNCTION("""COMPUTED_VALUE"""),"Y") -> Y | V31: =IFERROR(__xludf.DUMMYFUNCTION("""COMPUTED_VALUE"""),30.0) -> 30 | W31: =IFERROR(__xludf.DUMMYFUNCTION("""COMPUTED_VALUE"""),16.0) -> 16
A32: =IFERROR(__xludf.DUMMYFUNCTION("""COMPUTED_VALUE"""),"ถุงแกง-7*11") -> ถุงแกง-7*11 | B32: =IFERROR(__xludf.DUMMYFUNCTION("""COMPUTED_VALUE"""),10520.0) -> 10520 | C32: =IFERROR(__xludf.DUMMYFUNCTION("""COMPUTED_VALUE"""),"(S) ถุงแกง 7*11 ตราดาว") -> (S) ถุงแกง 7*11 ตราดาว | D32: =IFERROR(__xludf.DUMMYFUNCTION("""COMPUTED_VALUE"""),"**ของแห้ง") -> **ของแห้ง | E32: =IFERROR(__xludf.DUMMYFUNCTION("""COMPUTED_VALUE"""),"X") -> X | F32: =IFERROR(__xludf.DUMMYFUNCTION("""COMPUTED_VALUE"""),"N") -> N | M32: =IFERROR(__xludf.DUMMYFUNCTION("""COMPUTED_VALUE"""),34.0) -> 34 | N32: =IFERROR(__xludf.DUMMYFUNCTION("""COMPUTED_VALUE"""),8.859085900666E12) -> 8859085900666 | Q32: =IFERROR(__xludf.DUMMYFUNCTION("""COMPUTED_VALUE"""),"Y") -> Y | T32: =IFERROR(__xludf.DUMMYFUNCTION("""COMPUTED_VALUE"""),0.0) -> 0 | U32: =IFERROR(__xludf.DUMMYFUNCTION("""COMPUTED_VALUE"""),"Y") -> Y | V32: =IFERROR(__xludf.DUMMYFUNCTION("""COMPUTED_VALUE"""),45.0) -> 45 | W32: =IFERROR(__xludf.DUMMYFUNCTION("""COMPUTED_VALUE"""),37.0) -> 37 | X32: =IFERROR(__xludf.DUMMYFUNCTION("""COMPUTED_VALUE"""),10.0) -> 10
A33: =IFERROR(__xludf.DUMMYFUNCTION("""COMPUTED_VALUE"""),"ถุงแกง-8*12") -> ถุงแกง-8*12 | B33: =IFERROR(__xludf.DUMMYFUNCTION("""COMPUTED_VALUE"""),10474.0) -> 10474 | C33: =IFERROR(__xludf.DUMMYFUNCTION("""COMPUTED_VALUE"""),"(S) ถุงแกง 8*12 pp น้ำตาล") -> (S) ถุงแกง 8*12 pp น้ำตาล | D33: =IFERROR(__xludf.DUMMYFUNCTION("""COMPUTED_VALUE"""),"**ของแห้ง") -> **ของแห้ง | E33: =IFERROR(__xludf.DUMMYFUNCTION("""COMPUTED_VALUE"""),"X") -> X | F33: =IFERROR(__xludf.DUMMYFUNCTION("""COMPUTED_VALUE"""),"N") -> N | M33: =IFERROR(__xludf.DUMMYFUNCTION("""COMPUTED_VALUE"""),33.0) -> 33 | N33: =IFERROR(__xludf.DUMMYFUNCTION("""COMPUTED_VALUE"""),8.858817011212E12) -> 8858817011212 | Q33: =IFERROR(__xludf.DUMMYFUNCTION("""COMPUTED_VALUE"""),"Y") -> Y | T33: =IFERROR(__xludf.DUMMYFUNCTION("""COMPUTED_VALUE"""),0.0) -> 0 | U33: =IFERROR(__xludf.DUMMYFUNCTION("""COMPUTED_VALUE"""),"Y") -> Y | V33: =IFERROR(__xludf.DUMMYFUNCTION("""COMPUTED_VALUE"""),45.0) -> 45 | W33: =IFERROR(__xludf.DUMMYFUNCTION("""COMPUTED_VALUE"""),33.0) -> 33
A34: =IFERROR(__xludf.DUMMYFUNCTION("""COMPUTED_VALUE"""),"น้ำจิ้มชีฟู้ด") -> น้ำจิ้มชีฟู้ด | B34: =IFERROR(__xludf.DUMMYFUNCTION("""COMPUTED_VALUE"""),10015.0) -> 10015 | C34: =IFERROR(__xludf.DUMMYFUNCTION("""COMPUTED_VALUE"""),"(S) น้ำจิ้มซีฟู้ดฝาเขียว") -> (S) น้ำจิ้มซีฟู้ดฝาเขียว | F34: =IFERROR(__xludf.DUMMYFUNCTION("""COMPUTED_VALUE"""),"N") -> N | M34: =IFERROR(__xludf.DUMMYFUNCTION("""COMPUTED_VALUE"""),20.0) -> 20 | Q34: =IFERROR(__xludf.DUMMYFUNCTION("""COMPUTED_VALUE"""),"N") -> N | U34: =IFERROR(__xludf.DUMMYFUNCTION("""COMPUTED_VALUE"""),"Y") -> Y | V34: =IFERROR(__xludf.DUMMYFUNCTION("""COMPUTED_VALUE"""),30.0) -> 30
A35: =IFERROR(__xludf.DUMMYFUNCTION("""COMPUTED_VALUE"""),"น้ำตาลทรายแดง(วังขนาย)1,000กรัม") -> น้ำตาลทรายแดง(วังขนาย)1,000กรัม | B35: =IFERROR(__xludf.DUMMYFUNCTION("""COMPUTED_VALUE"""),11529.0) -> 11529 | C35: =IFERROR(__xludf.DUMMYFUNCTION("""COMPUTED_VALUE"""),"(S) น้ำตาลทรายแดง(วังขนาย)1,000กรัม") -> (S) น้ำตาลทรายแดง(วังขนาย)1,000กรัม | E35: =IFERROR(__xludf.DUMMYFUNCTION("""COMPUTED_VALUE"""),"X") -> X | F35: =IFERROR(__xludf.DUMMYFUNCTION("""COMPUTED_VALUE"""),"N") -> N | M35: =IFERROR(__xludf.DUMMYFUNCTION("""COMPUTED_VALUE"""),26.0) -> 26 | Q35: =IFERROR(__xludf.DUMMYFUNCTION("""COMPUTED_VALUE"""),"N") -> N | U35: =IFERROR(__xludf.DUMMYFUNCTION("""COMPUTED_VALUE"""),"Y") -> Y | V35: =IFERROR(__xludf.DUMMYFUNCTION("""COMPUTED_VALUE"""),35.0) -> 35
A36: =IFERROR(__xludf.DUMMYFUNCTION("""COMPUTED_VALUE"""),"น้ำมะนาวฟ้าไทย-1000ml") -> น้ำมะนาวฟ้าไทย-1000ml | B36: =IFERROR(__xludf.DUMMYFUNCTION("""COMPUTED_VALUE"""),10589.0) -> 10589 | C36: =IFERROR(__xludf.DUMMYFUNCTION("""COMPUTED_VALUE"""),"(S) น้ำมะนาวฟ้าไทย 1000ml") -> (S) น้ำมะนาวฟ้าไทย 1000ml | D36: =IFERROR(__xludf.DUMMYFUNCTION("""COMPUTED_VALUE"""),"**เครื่องปรุง") -> **เครื่องปรุง | E36: =IFERROR(__xludf.DUMMYFUNCTION("""COMPUTED_VALUE"""),"<p>X</p>") -> <p>X</p> | F36: =IFERROR(__xludf.DUMMYFUNCTION("""COMPUTED_VALUE"""),"N") -> N | M36: =IFERROR(__xludf.DUMMYFUNCTION("""COMPUTED_VALUE"""),21.67) -> 21.67 | N36: =IFERROR(__xludf.DUMMYFUNCTION("""COMPUTED_VALUE"""),8.854334002436E12) -> 8854334002436 | Q36: =IFERROR(__xludf.DUMMYFUNCTION("""COMPUTED_VALUE"""),"Y") -> Y | T36: =IFERROR(__xludf.DUMMYFUNCTION("""COMPUTED_VALUE"""),21.67) -> 21.67 | U36: =IFERROR(__xludf.DUMMYFUNCTION("""COMPUTED_VALUE"""),"Y") -> Y | V36: =IFERROR(__xludf.DUMMYFUNCTION("""COMPUTED_VALUE"""),25.0) -> 25 | W36: =IFERROR(__xludf.DUMMYFUNCTION("""COMPUTED_VALUE"""),0.0) -> 0
A37: =IFERROR(__xludf.DUMMYFUNCTION("""COMPUTED_VALUE"""),"น้ำมะนาวฟ้าไทย-300มล") -> น้ำมะนาวฟ้าไทย-300มล | B37: =IFERROR(__xludf.DUMMYFUNCTION("""COMPUTED_VALUE"""),11196.0) -> 11196 | C37: =IFERROR(__xludf.DUMMYFUNCTION("""COMPUTED_VALUE"""),"(S) น้ำมะนาวฟ้าไทย 300มล") -> (S) น้ำมะนาวฟ้าไทย 300มล | D37: =IFERROR(__xludf.DUMMYFUNCTION("""COMPUTED_VALUE"""),"**เครื่องปรุง") -> **เครื่องปรุง | E37: =IFERROR(__xludf.DUMMYFUNCTION("""COMPUTED_VALUE"""),"X") -> X | F37: =IFERROR(__xludf.DUMMYFUNCTION("""COMPUTED_VALUE"""),"N") -> N | M37: =IFERROR(__xludf.DUMMYFUNCTION("""COMPUTED_VALUE"""),7.9) -> 7.9 | N37: =IFERROR(__xludf.DUMMYFUNCTION("""COMPUTED_VALUE"""),8.854334005024E12) -> 8854334005024 | Q37: =IFERROR(__xludf.DUMMYFUNCTION("""COMPUTED_VALUE"""),"Y") -> Y | T37: =IFERROR(__xludf.DUMMYFUNCTION("""COMPUTED_VALUE"""),0.0) -> 0 | U37: =IFERROR(__xludf.DUMMYFUNCTION("""COMPUTED_VALUE"""),"Y") -> Y | V37: =IFERROR(__xludf.DUMMYFUNCTION("""COMPUTED_VALUE"""),15.0) -> 15 | W37: =IFERROR(__xludf.DUMMYFUNCTION("""COMPUTED_VALUE"""),0.0) -> 0 | X37: =IFERROR(__xludf.DUMMYFUNCTION("""COMPUTED_VALUE"""),0.0) -> 0
A38: =IFERROR(__xludf.DUMMYFUNCTION("""COMPUTED_VALUE"""),"น้ำปลาแท้ทิพรส-เหลือง-700ml") -> น้ำปลาแท้ทิพรส-เหลือง-700ml | B38: =IFERROR(__xludf.DUMMYFUNCTION("""COMPUTED_VALUE"""),10656.0) -> 10656 | C38: =IFERROR(__xludf.DUMMYFUNCTION("""COMPUTED_VALUE"""),"(S) น้ําปลา ทิพรส 700ml") -> (S) น้ําปลา ทิพรส 700ml | D38: =IFERROR(__xludf.DUMMYFUNCTION("""COMPUTED_VALUE"""),"**เครื่องปรุง") -> **เครื่องปรุง | E38: =IFERROR(__xludf.DUMMYFUNCTION("""COMPUTED_VALUE"""),"<p>X</p>") -> <p>X</p> | F38: =IFERROR(__xludf.DUMMYFUNCTION("""COMPUTED_VALUE"""),"N") -> N | M38: =IFERROR(__xludf.DUMMYFUNCTION("""COMPUTED_VALUE"""),28.77) -> 28.77 | N38: =IFERROR(__xludf.DUMMYFUNCTION("""COMPUTED_VALUE"""),8.850545777552E12) -> 8850545777552 | Q38: =IFERROR(__xludf.DUMMYFUNCTION("""COMPUTED_VALUE"""),"Y") -> Y | T38: =IFERROR(__xludf.DUMMYFUNCTION("""COMPUTED_VALUE"""),0.0) -> 0 | U38: =IFERROR(__xludf.DUMMYFUNCTION("""COMPUTED_VALUE"""),"Y") -> Y | V38: =IFERROR(__xludf.DUMMYFUNCTION("""COMPUTED_VALUE"""),35.0) -> 35 | W38: =IFERROR(__xludf.DUMMYFUNCTION("""COMPUTED_VALUE"""),-1.0) -> -1
A39: =IFERROR(__xludf.DUMMYFUNCTION("""COMPUTED_VALUE"""),"บะหมี่หยก-500g") -> บะหมี่หยก-500g | B39: =IFERROR(__xludf.DUMMYFUNCTION("""COMPUTED_VALUE"""),11255.0) -> 11255 | C39: =IFERROR(__xludf.DUMMYFUNCTION("""COMPUTED_VALUE"""),"(S) บะหมี่หยก 500g") -> (S) บะหมี่หยก 500g | D39: =IFERROR(__xludf.DUMMYFUNCTION("""COMPUTED_VALUE"""),"**เครื่องดื่ม") -> **เครื่องดื่ม | E39: =IFERROR(__xludf.DUMMYFUNCTION("""COMPUTED_VALUE"""),"<p>รุ่งโรจน์ (พุธ เสาร์)</p>") -> <p>รุ่งโรจน์ (พุธ เสาร์)</p> | F39: =IFERROR(__xludf.DUMMYFUNCTION("""COMPUTED_VALUE"""),"N") -> N | M39: =IFERROR(__xludf.DUMMYFUNCTION("""COMPUTED_VALUE"""),23.0) -> 23 | Q39: =IFERROR(__xludf.DUMMYFUNCTION("""COMPUTED_VALUE"""),"Y") -> Y | T39: =IFERROR(__xludf.DUMMYFUNCTION("""COMPUTED_VALUE"""),23.0) -> 23 | U39: =IFERROR(__xludf.DUMMYFUNCTION("""COMPUTED_VALUE"""),"Y") -> Y | V39: =IFERROR(__xludf.DUMMYFUNCTION("""COMPUTED_VALUE"""),30.0) -> 30 | W39: =IFERROR(__xludf.DUMMYFUNCTION("""COMPUTED_VALUE"""),17.0) -> 17 | X39: =IFERROR(__xludf.DUMMYFUNCTION("""COMPUTED_VALUE"""),0.0) -> 0
A40: =IFERROR(__xludf.DUMMYFUNCTION("""COMPUTED_VALUE"""),"(s)-ปูซิ่ง-500g") -> (s)-ปูซิ่ง-500g | B40: =IFERROR(__xludf.DUMMYFUNCTION("""COMPUTED_VALUE"""),31439.0) -> 31439 | C40: =IFERROR(__xludf.DUMMYFUNCTION("""COMPUTED_VALUE"""),"(s) ปูซิ่ง 500g") -> (s) ปูซิ่ง 500g | D40: =IFERROR(__xludf.DUMMYFUNCTION("""COMPUTED_VALUE"""),"TMP") -> TMP | E40: =IFERROR(__xludf.DUMMYFUNCTION("""COMPUTED_VALUE"""),"X") -> X | F40: =IFERROR(__xludf.DUMMYFUNCTION("""COMPUTED_VALUE"""),"N") -> N | O40: =IFERROR(__xludf.DUMMYFUNCTION("""COMPUTED_VALUE"""),11439.0) -> 11439 | P40: =IFERROR(__xludf.DUMMYFUNCTION("""COMPUTED_VALUE"""),1.0) -> 1 | Q40: =IFERROR(__xludf.DUMMYFUNCTION("""COMPUTED_VALUE"""),"N") -> N | R40: =IFERROR(__xludf.DUMMYFUNCTION("""COMPUTED_VALUE"""),"N") -> N | U40: =IFERROR(__xludf.DUMMYFUNCTION("""COMPUTED_VALUE"""),"Y") -> Y | V40: =IFERROR(__xludf.DUMMYFUNCTION("""COMPUTED_VALUE"""),69.0) -> 69
...

Sheet เช็คราคา
A1: 🥩 หมวดเนื้อหมู และเนื้อวัว (สไลด์/หมัก) | B1: ราคา | C1: ก.ก. ละ | F1: รหัสสินค้า | I1: =IFNA(CONCATENATE(VLOOKUP($G1,export_items!$B:$V,2,0)," @",VLOOKUP($G1,export_items!$B:$V,21,0)),"")
A2: สามชั้นหมัก นุ่ม งา A (ทองสุข) 5 กก./ถุง | B2: 590 | C2: =B2/5 -> 118 | F2: 10263 | H2: =CONCATENATE(VLOOKUP($F2,export_items!$B:$V,2,0)," @",VLOOKUP($F2,export_items!$B:$V,21,0)) -> สามชั้น A (นุ่ม) ทองสุข -118 @590 | I2: =IFNA(CONCATENATE(VLOOKUP($G2,export_items!$B:$V,2,0)," @",VLOOKUP($G2,export_items!$B:$V,21,0)),"")
A3: สามชั้นหมัก นุ่ม งา (4K) 5 กก./ถุง | B3: 765 | C3: =B3/5 -> 153 | F3: 10676 | H3: =CONCATENATE(VLOOKUP($F3,export_items!$B:$V,2,0)," @",VLOOKUP($F3,export_items!$B:$V,21,0)) -> สามชั้น 4k นุ่ม - 153 @765 | I3: =IFNA(CONCATENATE(VLOOKUP($G3,export_items!$B:$V,2,0)," @",VLOOKUP($G3,export_items!$B:$V,21,0)),"")
A4: สามชั้นหมัก นุ่ม งา (2K) 5 กก./ถุง | B4: 525 | C4: =B4/5 -> 105 | F4: 10671 | H4: =CONCATENATE(VLOOKUP($F4,export_items!$B:$V,2,0)," @",VLOOKUP($F4,export_items!$B:$V,21,0)) -> สามชั้น 2k (นุ่ม) - 105 @525 | I4: =IFNA(CONCATENATE(VLOOKUP($G4,export_items!$B:$V,2,0)," @",VLOOKUP($G4,export_items!$B:$V,21,0)),"")
A5: สามชั้น นุ่ม งา (ถุงใส) งา 5 กก./ถุง | B5: 490 | C5: =B5/5 -> 98 | F5: 10682 | H5: =CONCATENATE(VLOOKUP($F5,export_items!$B:$V,2,0)," @",VLOOKUP($F5,export_items!$B:$V,21,0)) -> สามชั้น (ถุงใส) งา - 98 @490 | I5: =IFNA(CONCATENATE(VLOOKUP($G5,export_items!$B:$V,2,0)," @",VLOOKUP($G5,export_items!$B:$V,21,0)),"")
A6: หมูหมัก นุ่ม งา (ถุงใส) 5 กก./ถุง | B6: 375 | C6: =B6/5 -> 75 | F6: 10514 | H6: =CONCATENATE(VLOOKUP($F6,export_items!$B:$V,2,0)," @",VLOOKUP($F6,export_items!$B:$V,21,0)) -> หมูหมัก(ถุงใส) นุ่ม -75 @375 | I6: =IFNA(CONCATENATE(VLOOKUP($G6,export_items!$B:$V,2,0)," @",VLOOKUP($G6,export_items!$B:$V,21,0)),"")
A7: หมูหมัก สมชาย 5 กก./ถุง | B7: 400 | C7: =B7/5 -> 80 | F7: 10159 | H7: =CONCATENATE(VLOOKUP($F7,export_items!$B:$V,2,0)," @",VLOOKUP($F7,export_items!$B:$V,21,0)) -> หมูนุ่ม (สมชาย) 5 กก. - 80 @400 | I7: =IFNA(CONCATENATE(VLOOKUP($G7,export_items!$B:$V,2,0)," @",VLOOKUP($G7,export_items!$B:$V,21,0)),"")
A8: สามชั้นหมัก พีเมี่ยม (VJ) 5 กก. | B8: 725 | C8: =B8/5 -> 145 | F8: 11379 | H8: =CONCATENATE(VLOOKUP($F8,export_items!$B:$V,2,0)," @",VLOOKUP($F8,export_items!$B:$V,21,0)) -> สามชั้น พีเมียม Vj ถุง5kg(145) @725 | I8: =IFNA(CONCATENATE(VLOOKUP($G8,export_items!$B:$V,2,0)," @",VLOOKUP($G8,export_items!$B:$V,21,0)),"")
A9: ลอกหนัง (ถุงใส) 5 กก. (หิ้ว) | B9: 490 | C9: =B9/5 -> 98 | F9: 10196 | H9: =CONCATENATE(VLOOKUP($F9,export_items!$B:$V,2,0)," @",VLOOKUP($F9,export_items!$B:$V,21,0)) -> ลอกหนัง (ถุงใส) 5 กก. (หิ้ว) - 98 @490 | I9: =IFNA(CONCATENATE(VLOOKUP($G9,export_items!$B:$V,2,0)," @",VLOOKUP($G9,export_items!$B:$V,21,0)),"")
A10: ลอกหนัง TS 5 กก. (หิ้ว) | B10: 475 | C10: =B10/5 -> 95 | F10: 10154 | H10: =CONCATENATE(VLOOKUP($F10,export_items!$B:$V,2,0)," @",VLOOKUP($F10,export_items!$B:$V,21,0)) -> ลอกหนัง TS 5 กก. (หิ้ว) - 95 @475 | I10: =IFNA(CONCATENATE(VLOOKUP($G10,export_items!$B:$V,2,0)," @",VLOOKUP($G10,export_items!$B:$V,21,0)),"")
A11: หมูชาบู (ฟ้า) 5 กก. (หิ้ว) | B11: 475 | C11: =B11/5 -> 95 | F11: 10895 | H11: =CONCATENATE(VLOOKUP($F11,export_items!$B:$V,2,0)," @",VLOOKUP($F11,export_items!$B:$V,21,0)) -> หมูชาบู(ฟ้า) 5 กก/หิ้ว -95 @475 | I11: =IFNA(CONCATENATE(VLOOKUP($G11,export_items!$B:$V,2,0)," @",VLOOKUP($G11,export_items!$B:$V,21,0)),"")
A12: หมูกลม TS 5 กก. (หิ้ว) | B12: 475 | C12: =B12/5 -> 95 | F12: 10155 | H12: =CONCATENATE(VLOOKUP($F12,export_items!$B:$V,2,0)," @",VLOOKUP($F12,export_items!$B:$V,21,0)) -> หมูกลม TS 5 กก (หิ้ว) - 95 @475 | I12: =IFNA(CONCATENATE(VLOOKUP($G12,export_items!$B:$V,2,0)," @",VLOOKUP($G12,export_items!$B:$V,21,0)),"")
A13: สันคอชาบู หมูอร่อย 5 กก./หิ้วเขียว | B13: 550 | C13: =B13/5 -> 110 | F13: 10898 | H13: =CONCATENATE(VLOOKUP($F13,export_items!$B:$V,2,0)," @",VLOOKUP($F13,export_items!$B:$V,21,0)) -> สันคอชาบู หมูอร่อย 5 กก./หิ้วเขียว - 110 @550 | I13: =IFNA(CONCATENATE(VLOOKUP($G13,export_items!$B:$V,2,0)," @",VLOOKUP($G13,export_items!$B:$V,21,0)),"")
... A25: เนื้อสไลด์ (ถุงแดง) 5 กก.(หิ้ว) | B25: 740 | C25: =B25/5 -> 148 | F25: 10977 | H25: =CONCATENATE(VLOOKUP($F25,export_items!$B:$V,2,0)," @",VLOOKUP($F25,export_items!$B:$V,21,0)) -> เนื้อสไลด์ (ถุงแดง) 5 กก.(หิ้ว) - 148 @740 | I25: =IFNA(CONCATENATE(VLOOKUP($G25,export_items!$B:$V,2,0)," @",VLOOKUP($G25,export_items!$B:$V,21,0)),"")
A26: เนื้อวัวนุ่ม (สมชาย) 2 กก./ถุง | B26: 190 | C26: =B26/2 -> 95 | F26: 11543 | H26: =CONCATENATE(VLOOKUP($F26,export_items!$B:$V,2,0)," @",VLOOKUP($F26,export_items!$B:$V,21,0)) -> เนื้อวัวนุ่ม (สมชาย) 2 กก./ถุง - 95 @190 | I26: =IFNA(CONCATENATE(VLOOKUP($G26,export_items!$B:$V,2,0)," @",VLOOKUP($G26,export_items!$B:$V,21,0)),"")
A27: หมูเด้งหลอด 5 แพ็ค (หิ้ว) | B27: 400 | C27: =B27/5 -> 80 | F27: 11251 | H27: =CONCATENATE(VLOOKUP($F27,export_items!$B:$V,2,0)," @",VLOOKUP($F27,export_items!$B:$V,21,0)) -> หมูเด้งหลอด 5 แพ็ค (หิ้ว) @400 | I27: =IFNA(CONCATENATE(VLOOKUP($G27,export_items!$B:$V,2,0)," @",VLOOKUP($G27,export_items!$B:$V,21,0)),"")
A28: หมูนุ่ม เบทาโกร (ลัง) | B28: 980 | C28: =B28/10 -> 98 | F28: 10300 | H28: =CONCATENATE(VLOOKUP($F28,export_items!$B:$V,2,0)," @",VLOOKUP($F28,export_items!$B:$V,21,0)) -> หมูนุ่มเบทาโกร 10*1 Kg ลัง @980 | I28: =IFNA(CONCATENATE(VLOOKUP($G28,export_items!$B:$V,2,0)," @",VLOOKUP($G28,export_items!$B:$V,21,0)),"")
A29: หมูนุ่มหมักปรุงรส เบทาโกร (ลัง) | B29: 900 | C29: =B29/10 -> 90 | F29: 10709 | H29: =CONCATENATE(VLOOKUP($F29,export_items!$B:$V,2,0)," @",VLOOKUP($F29,export_items!$B:$V,21,0)) -> หมูนุ่มหมักปรุงรส ลัง10กก -90 @900 | I29: =IFNA(CONCATENATE(VLOOKUP($G29,export_items!$B:$V,2,0)," @",VLOOKUP($G29,export_items!$B:$V,21,0)),"")
I30: =IFNA(CONCATENATE(VLOOKUP($G30,export_items!$B:$V,2,0)," @",VLOOKUP($G30,export_items!$B:$V,21,0)),"")
A31: 🥗 หมวดเครื่องใน และของยำ | B31: ราคา | C31: ก.ก. ละ | F31: รหัสสินค้า | H31: =CONCATENATE(VLOOKUP($F31,export_items!$B:$V,2,0)," @",VLOOKUP($F31,export_items!$B:$V,21,0)) -> #N/A | I31: =IFNA(CONCATENATE(VLOOKUP($G31,export_items!$B:$V,2,0)," @",VLOOKUP($G31,export_items!$B:$V,21,0)),"")
A32: ขายำ 5 กก./ถุง | B32: 300 | C32: =B32/5 -> 60 | F32: 10286 | H32: =CONCATENATE(VLOOKUP($F32,export_items!$B:$V,2,0)," @",VLOOKUP($F32,export_items!$B:$V,21,0)) -> ขายำ 5 กก./ถุง - 60 @300 | I32: =IFNA(CONCATENATE(VLOOKUP($G32,export_items!$B:$V,2,0)," @",VLOOKUP($G32,export_items!$B:$V,21,0)),"")
A33: หมึกกรอบหั่น 5 กก./ถุง | B33: 515 | C33: =B33/5 -> 103 | F33: 10232 | H33: =CONCATENATE(VLOOKUP($F33,export_items!$B:$V,2,0)," @",VLOOKUP($F33,export_items!$B:$V,21,0)) -> หมึกกรอบหั่น 5 กก./ถุง - 103 @515 | I33: =IFNA(CONCATENATE(VLOOKUP($G33,export_items!$B:$V,2,0)," @",VLOOKUP($G33,export_items!$B:$V,21,0)),"")
A34: หมึกกรอบตัว 5 กก./ถุง | B34: 515 | C34: =B34/5 -> 103 | F34: 10335 | H34: =CONCATENATE(VLOOKUP($F34,export_items!$B:$V,2,0)," @",VLOOKUP($F34,export_items!$B:$V,21,0)) -> หมึกกรอบตัว 5 กก./ถุง - 103 @515 | I34: =IFNA(CONCATENATE(VLOOKUP($G34,export_items!$B:$V,2,0)," @",VLOOKUP($G34,export_items!$B:$V,21,0)),"")
A35: สไบหั่น 5 กก./ถุง | B35: 690 | C35: =B35/5 -> 138 | F35: 10233 | H35: =CONCATENATE(VLOOKUP($F35,export_items!$B:$V,2,0)," @",VLOOKUP($F35,export_items!$B:$V,21,0)) -> สไบหั่น 5กก/ถุง -138 @690 | I35: =IFNA(CONCATENATE(VLOOKUP($G35,export_items!$B:$V,2,0)," @",VLOOKUP($G35,export_items!$B:$V,21,0)),"")
A36: สไบผืน A 5 กก./ถุง | B36: 775 | C36: =B36/5 -> 155 | F36: 10373 | H36: =CONCATENATE(VLOOKUP($F36,export_items!$B:$V,2,0)," @",VLOOKUP($F36,export_items!$B:$V,21,0)) -> สไบผืน A 5 กก./ถุง - 155 @775 | I36: =IFNA(CONCATENATE(VLOOKUP($G36,export_items!$B:$V,2,0)," @",VLOOKUP($G36,export_items!$B:$V,21,0)),"")
A37: สไบจุก 5 กก./ถุง | B37: 660 | C37: =B37/5 -> 132 | F37: 11421 | H37: =CONCATENATE(VLOOKUP($F37,export_items!$B:$V,2,0)," @",VLOOKUP($F37,export_items!$B:$V,21,0)) -> สไบจุก 5 กก/ถุง -132 @660 | I37: =IFNA(CONCATENATE(VLOOKUP($G37,export_items!$B:$V,2,0)," @",VLOOKUP($G37,export_items!$B:$V,21,0)),"")
A38: ไส้ตันเล็ก 5 กก./ถุง | B38: 590 | C38: =B38/5 -> 118 | F38: 10302 | H38: =CONCATENATE(VLOOKUP($F38,export_items!$B:$V,2,0)," @",VLOOKUP($F38,export_items!$B:$V,21,0)) -> ไส้ตันเล็ก 5 กก./ถุง - 118 @590 | I38: =IFNA(CONCATENATE(VLOOKUP($G38,export_items!$B:$V,2,0)," @",VLOOKUP($G38,export_items!$B:$V,21,0)),"")
A39: ไส้ตันกลาง 5 กก./ถุง | B39: 725 | C39: =B39/5 -> 145 | F39: 10303 | H39: =CONCATENATE(VLOOKUP($F39,export_items!$B:$V,2,0)," @",VLOOKUP($F39,export_items!$B:$V,21,0)) -> ไส้ตันกลาง 5 กก./ถุง - 145 @725 | I39: =IFNA(CONCATENATE(VLOOKUP($G39,export_items!$B:$V,2,0)," @",VLOOKUP($G39,export_items!$B:$V,21,0)),"")
A40: ไข่นกกระทา 500 กรัม 10 ถุง(หิ้ว) | B40: 780 | C40: =B40/10 -> 78 | F40: 31431 | H40: =CONCATENATE(VLOOKUP($F40,export_items!$B:$V,2,0)," @",VLOOKUP($F40,export_items!$B:$V,21,0)) -> ไข่นกกระทา 500 กรัม 10 ถุง(หิ้ว) - 78 @780 | I40: =IFNA(CONCATENATE(VLOOKUP($G40,export_items!$B:$V,2,0)," @",VLOOKUP($G40,export_items!$B:$V,21,0)),"")
A41: แมงกะพรุนจืด 5 กก.(หิ้ว) | B41: 450 | C41: =B41/5 -> 90 | F41: 10468 | H41: =CONCATENATE(VLOOKUP($F41,export_items!$B:$V,2,0)," @",VLOOKUP($F41,export_items!$B:$V,21,0)) -> แมงกะพรุนจืด 5 กก.(หิ้ว) - 90 @450 | I41: =IFNA(CONCATENATE(VLOOKUP($G41,export_items!$B:$V,2,0)," @",VLOOKUP($G41,export_items!$B:$V,21,0)),"")
I42: =IFNA(CONCATENATE(VLOOKUP($G42,export_items!$B:$V,2,0)," @",VLOOKUP($G42,export_items!$B:$V,21,0)),"")
A43: 🦑 หมวดอาหารทะเล (หมึก ปลา ชิ้น) | B43: ราคา | C43: ก.ก. ละ | D43: แบ่งขาย | F43: รหัสสินค้า | I43: =IFNA(CONCATENATE(VLOOKUP($G43,export_items!$B:$V,2,0)," @",VLOOKUP($G43,export_items!$B:$V,21,0)),"")
A44: หมึกบั้ง A (ลัง) | B44: 540 | C44: =B44/10 -> 54 | D44: 68 | F44: 10122 | G44: 10121 | H44: =CONCATENATE(VLOOKUP($F44,export_items!$B:$V,2,0)," @",VLOOKUP($F44,export_items!$B:$V,21,0)) -> หมึกบั้ง A (ลัง) - 54 @540 | I44: =IFNA(CONCATENATE(VLOOKUP($G44,export_items!$B:$V,2,0)," @",VLOOKUP($G44,export_items!$B:$V,21,0)),"") -> (S) หมึกบั้งA แพ็ค 1Kg @68
A45: หมึกวง (ลัง) | B45: 590 | C45: =B45/10 -> 59 | D45: 65 | F45: 11359 | G45: 11357 | H45: =CONCATENATE(VLOOKUP($F45,export_items!$B:$V,2,0)," @",VLOOKUP($F45,export_items!$B:$V,21,0)) -> หมึกวง (ลัง) - 59 @590 | I45: =IFNA(CONCATENATE(VLOOKUP($G45,export_items!$B:$V,2,0)," @",VLOOKUP($G45,export_items!$B:$V,21,0)),"") -> (S) หมึกวง แพ็ค 1kg(65) @65
A46: หนวดหั่น (ลัง) | B46: 550 | C46: =B46/10 -> 55 | D46: 63 | F46: 10429 | G46: 10013 | H46: =CONCATENATE(VLOOKUP($F46,export_items!$B:$V,2,0)," @",VLOOKUP($F46,export_items!$B:$V,21,0)) -> หนวดหั่น (ลัง) @550 | I46: =IFNA(CONCATENATE(VLOOKUP($G46,export_items!$B:$V,2,0)," @",VLOOKUP($G46,export_items!$B:$V,21,0)),"") -> หนวดหั่น 1Kg @63
A47: หนวดเบบี๋จิ๋ว (ลัง) | B47: 600 | C47: =B47/10 -> 60 | D47: 70 | F47: 10609 | G47: 10123 | H47: =CONCATENATE(VLOOKUP($F47,export_items!$B:$V,2,0)," @",VLOOKUP($F47,export_items!$B:$V,21,0)) -> หนวดเบบี๋จิ๋ว (ลัง) @600 | I47: =IFNA(CONCATENATE(VLOOKUP($G47,export_items!$B:$V,2,0)," @",VLOOKUP($G47,export_items!$B:$V,21,0)),"") -> หนวดเบบี๋จิ๋ว แพ็ค 1Kg @70
A48: หมึกวงติดปีก (ลัง) | B48: 570 | C48: =B48/10 -> 57 | D48: 60 | F48: 10201 | G48: 10200 | H48: =CONCATENATE(VLOOKUP($F48,export_items!$B:$V,2,0)," @",VLOOKUP($F48,export_items!$B:$V,21,0)) -> หมึกวงติดปีก (ลัง) - 57 @570 | I48: =IFNA(CONCATENATE(VLOOKUP($G48,export_items!$B:$V,2,0)," @",VLOOKUP($G48,export_items!$B:$V,21,0)),"") -> (S) หมึกวงติดปีก ถุง1 กก(60) @60
A49: หมึกบั้งมะเฟือง (ลัง) | B49: 630 | C49: =B49/10 -> 63 | D49: 70 | F49: 10306 | G49: 10305 | H49: =CONCATENATE(VLOOKUP($F49,export_items!$B:$V,2,0)," @",VLOOKUP($F49,export_items!$B:$V,21,0)) -> หมึกบั้งมะเฟือง (ลัง) @630 | I49: =IFNA(CONCATENATE(VLOOKUP($G49,export_items!$B:$V,2,0)," @",VLOOKUP($G49,export_items!$B:$V,21,0)),"") -> (S) หมึกบั้งมะเฟือง 1 Kg @70
A50: หมึกดอกไม้ A (ลัง) | B50: 610 | C50: =B50/10 -> 61 | D50: 69 | F50: 10044 | G50: 10043 | H50: =CONCATENATE(VLOOKUP($F50,export_items!$B:$V,2,0)," @",VLOOKUP($F50,export_items!$B:$V,21,0)) -> หมึกดอกไม้ A (ลัง) @610 | I50: =IFNA(CONCATENATE(VLOOKUP($G50,export_items!$B:$V,2,0)," @",VLOOKUP($G50,export_items!$B:$V,21,0)),"") -> หมึกดอกไม้ 1Kg @69
A51: ปลายหนวด ติดโคน (ลัง) | B51: 770 | C51: =B51/10 -> 77 | D51: 85 | F51: 11420 | G51: 11419 | H51: =CONCATENATE(VLOOKUP($F51,export_items!$B:$V,2,0)," @",VLOOKUP($F51,export_items!$B:$V,21,0)) -> ปลายหนวด ติดโคน (ลัง) @770 | I51: =IFNA(CONCATENATE(VLOOKUP($G51,export_items!$B:$V,2,0)," @",VLOOKUP($G51,export_items!$B:$V,21,0)),"") -> ปลายหนวด ติดโคน 1กก @85
...

Sheet หมูกระทะ
A1: =CONCATENATE( "ข้อมูล ณ วันที่ ", CHAR(10), TEXT(TODAY(), "dd/mm/yyyy"), CHAR(10),"ราคาอาจมีการเปลี่ยนแปลง") -> ข้อมูล ณ วันที่ 30/10/2026 ราคาอาจมีการเปลี่ยนแปลง
A2: {=Pork1} -> 🥩 หมวดเนื้อหมู และเนื้อวัว (สไลด์/หมัก) | B2: ราคา | C2: ก.ก. ละ | E2: {=Pices} -> 🦑 หมวดอาหารทะเล (หมึก ปลา ชิ้น) | F2: ราคา | G2: ก.ก. ละ | H2: แบ่งขาย
A3: สามชั้นหมัก นุ่ม งา A (ทองสุข) 5 กก./ถุง | B3: 590 | C3: 118 | E3: หมึกบั้ง A (ลัง) | F3: 540 | G3: 54 | H3: 68
A4: สามชั้นหมัก นุ่ม งา (4K) 5 กก./ถุง | B4: 765 | C4: 153 | E4: หมึกวง (ลัง) | F4: 590 | G4: 59 | H4: 65
A5: สามชั้นหมัก นุ่ม งา (2K) 5 กก./ถุง | B5: 525 | C5: 105 | E5: หนวดหั่น (ลัง) | F5: 550 | G5: 55 | H5: 63
A6: สามชั้น นุ่ม งา (ถุงใส) งา 5 กก./ถุง | B6: 490 | C6: 98 | E6: หนวดเบบี๋จิ๋ว (ลัง) | F6: 600 | G6: 60 | H6: 70
A7: หมูหมัก นุ่ม งา (ถุงใส) 5 กก./ถุง | B7: 375 | C7: 75 | E7: หมึกวงติดปีก (ลัง) | F7: 570 | G7: 57 | H7: 60
A8: หมูหมัก สมชาย 5 กก./ถุง | B8: 400 | C8: 80 | E8: หมึกบั้งมะเฟือง (ลัง) | F8: 630 | G8: 63 | H8: 70
A9: สามชั้นหมัก พีเมี่ยม (VJ) 5 กก. | B9: 725 | C9: 145 | E9: หมึกดอกไม้ A (ลัง) | F9: 610 | G9: 61 | H9: 69
A10: ลอกหนัง (ถุงใส) 5 กก. (หิ้ว) | B10: 490 | C10: 98 | E10: ปลายหนวด ติดโคน (ลัง) | F10: 770 | G10: 77 | H10: 85
A11: ลอกหนัง TS 5 กก. (หิ้ว) | B11: 475 | C11: 95 | E11: ปลายหนวด เรด้ามิกซ์ (ลัง) | F11: 630 | G11: 63
A12: หมูชาบู (ฟ้า) 5 กก. (หิ้ว) | B12: 475 | C12: 95 | E12: ปลายหนวด A (ลัง) | F12: 830 | G12: 83
A13: หมูกลม TS 5 กก. (หิ้ว) | B13: 475 | C13: 95 | E13: คอเอ็นแก้ว (ลัง) | F13: 390 | G13: 39
A14: สันคอชาบู หมูอร่อย 5 กก./หิ้วเขียว | B14: 550 | C14: 110 | E14: ดอลลี่หั่น (น้ำเงิน) (ลัง) | F14: 470 | G14: 47
A15: ชาบูนมสด หมูอร่อย 5 กก./หิ้วชมพู | B15: 550 | C15: 110 | E15: ดอลลี่หั่น (น้ำตาล) (ลัง) | F15: 680 | G15: 68 | H15: 70
A16: หมูชาบู 3 แถว 5 กก. (หิ้ว) | B16: 475 | C16: 95 | E16: ดอลลี่ตัว (เขียว) (ลัง) | F16: 560 | G16: 56
A17: หมูชาบู (หอม) 5กก (หิ้ว) | B17: 560 | C17: 112 | E17: ดอลลี่ตัว (น้ำตาล) (ลัง) | F17: 650 | G17: 65 | H17: 85
A18: คุโรบุตะ ถุงใส 5 กก. (หิ้ว) | B18: 525 | C18: 105 | E18: ท้องม่อน (ลัง) | F18: 840 | G18: 84 | H18: 90
A19: คุโรบุตะ (สมชาย) 5 กก. (หิ้ว) | B19: 650 | C19: 130
A20: สามชั้นลอก (เรียง) 1 กก. (หิ้ว) | B20: 725 | C20: 145 | E20: {=Fried} -> 🍟 หมวดของทานเล่น และของทอด | F20: ราคา | G20: ก.ก. ละ | H20: แบ่งขาย
A21: ลอก (ไม่เรียง) (ถุง 5 กก.) | B21: 675 | C21: 135 | E21: ขนมจีบไส้ทะลัก 1กก. (หิ้ว) | F21: 1000 | G21: 100 | H21: 105
A22: สามชั้นสไลด์ A (ถุง 5 กก.) | B22: 925 | C22: 185 | E22: ขนมจีบหมู 390 กรัม 10 แพ็ค (ลัง) | F22: 630 | G22: 63 | H22: 65
A23: สันคอ Mfood (เหลือง) 5 กก.(หิ้ว) | B23: 740 | C23: 148 | E23: ฟองเต้าหู้ถาด 32 แพ็ค (ลัง) | F23: 1180 | G23: 36.875 | H23: 48
A24: ชาบูกลม Mfood (เขียว) 5 กก.(หิ้ว) | B24: 595 | C24: 119 | E24: เฟรนช์ฟรายส์ วีนัส 7 มิล (ลัง) | F24: 530 | G24: 53 | H24: 70
A25: สามชั้นเทียม Mfood ด 5 กก.(หิ้ว) | B25: 715 | C25: 143 | E25: เฟรนช์ฟรายส์ ยูเรนัส 10 มิล (ลัง) | F25: 530 | G25: 53 | H25: 70
A26: เนื้อสไลด์ (ถุงแดง) 5 กก.(หิ้ว) | B26: 740 | C26: 148 | E26: เฟรนช์ฟรายส์ หยัก (ลัง) | F26: 530 | G26: 53 | H26: 70
A27: เนื้อวัวนุ่ม (สมชาย) 2 กก./ถุง | B27: 190 | C27: 95 | E27: นักเก็ตไก่ ซันเวลเล่ (ลัง) | F27: 1150 | G27: 115 | H27: 120
A28: หมูเด้งหลอด 5 แพ็ค (หิ้ว) | B28: 400 | C28: 80 | E28: นักเก็ต ถุงชมพู 8 กก. (ลัง) | F28: 800 | G28: 100
A29: หมูนุ่ม เบทาโกร (ลัง) | B29: 980 | C29: 98 | E29: ไก่ป๊อป ซันเวลเล่ (ลัง) | F29: 1120 | G29: 112
A30: หมูนุ่มหมักปรุงรส เบทาโกร (ลัง) | B30: 900 | C30: 90 | E30: ซาลาเปา 20 ลูก ไส้ครีม 14 แพ็ค (ลัง) | F30: 1120 | G30: 80 | H30: 85
E32: {=InPork} -> 🥓 หมวดเครื่องในหมู | F32: ราคา | G32: ก.ก. ละ | H32: แบ่งขาย
A33: {=Nammmm} -> 🥗 หมวดเครื่องใน และของยำ | B33: ราคา | C33: ก.ก. ละ | E33: ตับหมู ลัง 10 กก. | F33: 850 | G33: 85 | H33: 90
A34: ขายำ 5 กก./ถุง | B34: 300 | C34: 60 | E34: ตับหมูสไลด์ แพ็ค 1 กก. | F34: 90
A35: หมึกกรอบหั่น 5 กก./ถุง | B35: 515 | C35: 103 | E35: จี้หมู ลัง 10 กก. | F35: 900 | G35: 90 | H35: 90
A36: หมึกกรอบตัว 5 กก./ถุง | B36: 515 | C36: 103 | E36: จี้หมูสไลด์ แพ็ค 1 กก. | F36: 95
A37: สไบหั่น 5 กก./ถุง | B37: 690 | C37: 138
A38: สไบผืน A 5 กก./ถุง | B38: 775 | C38: 155 | E38: {=Source} -> 🍄 หมวดเห็ด สาหร่าย และน้ำจิ้ม | F38: ราคา | G38: ก.ก. ละ | H38: แบ่งขาย
A39: สไบจุก 5 กก./ถุง | B39: 660 | C39: 132 | E39: ยำสาหร่าย (ลัง) | F39: 950 | G39: 95 | H39: 105
A40: ไส้ตันเล็ก 5 กก./ถุง | B40: 590 | C40: 118 | E40: เห็ดแห้ง 500 กรัม * 8 แพ็ค (ลัง) | F40: 1180 | G40: 147.5 | H40: 170
A41: ไส้ตันกลาง 5 กก./ถุง | B41: 725 | C41: 145 | E41: น้ำจิ้มแชมป์ เล็ก (ลัง) | F41: 840 | G41: 210 | H41: 215
...

Sheet ชาบู
A1: =CONCATENATE( "ข้อมูล ณ วันที่ ", CHAR(10), TEXT(TODAY(), "dd/mm/yyyy"), CHAR(10),"ราคาอาจมีการเปลี่ยนแปลง") -> ข้อมูล ณ วันที่ 30/10/2026 ราคาอาจมีการเปลี่ยนแปลง
A2: {=bar} -> 🥩 หมวด แท่งหมูและเนื้อวัว (ขึ้นรูป) | B2: ราคา | C2: ก.ก. ละ | E2: {=Pices} -> 🦑 หมวดอาหารทะเล (หมึก ปลา ชิ้น) | F2: ราคา | G2: ก.ก. ละ | H2: แบ่งขาย
A3: สามชั้นแท่ง เบทาโกร | B3: 170 | C3: 170 | E3: หมึกบั้ง A (ลัง) | F3: 540 | G3: 54 | H3: 68
A4: สันคอแท่ง เบทาโกร | B4: 160 | C4: 160 | E4: หมึกวง (ลัง) | F4: 590 | G4: 59 | H4: 65
A5: สันนอกแท่ง เบทาโกร | B5: 125 | C5: 125 | E5: หนวดหั่น (ลัง) | F5: 550 | G5: 55 | H5: 63
A6: เนื้อเสือออส | B6: 290 | C6: 290 | E6: หนวดเบบี๋จิ๋ว (ลัง) | F6: 600 | G6: 60 | H6: 70
A7: เนื้อน่องลาย โคขุน | B7: 208 | C7: 208 | E7: หมึกวงติดปีก (ลัง) | F7: 570 | G7: 57 | H7: 60
A8: สันคอ โคขุน | B8: 187 | C8: 187 | E8: หมึกบั้งมะเฟือง (ลัง) | F8: 630 | G8: 63 | H8: 70
A9: ใบพาย (เต็ม) โคขุน | B9: 197 | C9: 197 | E9: หมึกดอกไม้ A (ลัง) | F9: 610 | G9: 61 | H9: 69
A10: ใบพาย (ใบไม้)โคขุน | B10: 225 | C10: 225 | E10: ปลายหนวด ติดโคน (ลัง) | F10: 770 | G10: 77 | H10: 85
A11: เสือ โคขุน | B11: 205 | C11: 205 | E11: ปลายหนวด เรด้ามิกซ์ (ลัง) | F11: 630 | G11: 63
A12: ริบอาย โคขุน | B12: 198 | C12: 198 | E12: ปลายหนวด A (ลัง) | F12: 830 | G12: 83
E13: คอเอ็นแก้ว (ลัง) | F13: 390 | G13: 39
A14: {=Pork1} -> 🥩 หมวดเนื้อหมู และเนื้อวัว (สไลด์/หมัก) | B14: ราคา | C14: ก.ก. ละ | E14: ดอลลี่หั่น (น้ำเงิน) (ลัง) | F14: 470 | G14: 47
A15: สามชั้นหมัก นุ่ม งา A (ทองสุข) 5 กก./ถุง | B15: 590 | C15: 118 | E15: ดอลลี่หั่น (น้ำตาล) (ลัง) | F15: 680 | G15: 68 | H15: 70
A16: สามชั้นหมัก นุ่ม งา (4K) 5 กก./ถุง | B16: 765 | C16: 153 | E16: ดอลลี่ตัว (เขียว) (ลัง) | F16: 560 | G16: 56
A17: สามชั้นหมัก นุ่ม งา (2K) 5 กก./ถุง | B17: 525 | C17: 105 | E17: ดอลลี่ตัว (น้ำตาล) (ลัง) | F17: 650 | G17: 65 | H17: 85
A18: สามชั้น นุ่ม งา (ถุงใส) งา 5 กก./ถุง | B18: 490 | C18: 98 | E18: ท้องม่อน (ลัง) | F18: 840 | G18: 84 | H18: 90
